[2023-10-18T11:17:43.276+0000] {taskinstance.py:1159} INFO - Dependencies all met for dep_context=non-requeueable deps ti=<TaskInstance: copy_tranform_to_mongo.transform_data_by_pandas scheduled__2021-05-04T00:00:00+00:00 [queued]>
[2023-10-18T11:17:43.290+0000] {taskinstance.py:1159} INFO - Dependencies all met for dep_context=requeueable deps ti=<TaskInstance: copy_tranform_to_mongo.transform_data_by_pandas scheduled__2021-05-04T00:00:00+00:00 [queued]>
[2023-10-18T11:17:43.291+0000] {taskinstance.py:1361} INFO - Starting attempt 1 of 1
[2023-10-18T11:17:43.307+0000] {taskinstance.py:1382} INFO - Executing <Task(DockerOperator): transform_data_by_pandas> on 2021-05-04 00:00:00+00:00
[2023-10-18T11:17:43.313+0000] {standard_task_runner.py:57} INFO - Started process 568 to run task
[2023-10-18T11:17:43.315+0000] {standard_task_runner.py:84} INFO - Running: ['***', 'tasks', 'run', 'copy_tranform_to_mongo', 'transform_data_by_pandas', 'scheduled__2021-05-04T00:00:00+00:00', '--job-id', '214', '--raw', '--subdir', 'DAGS_FOLDER/file_***-mongo.py', '--cfg-path', '/tmp/tmpydy68hf7']
[2023-10-18T11:17:43.316+0000] {standard_task_runner.py:85} INFO - Job 214: Subtask transform_data_by_pandas
[2023-10-18T11:17:43.355+0000] {task_command.py:416} INFO - Running <TaskInstance: copy_tranform_to_mongo.transform_data_by_pandas scheduled__2021-05-04T00:00:00+00:00 [running]> on host 0e68aa52dfc7
[2023-10-18T11:17:43.423+0000] {taskinstance.py:1662} INFO - Exporting env vars: AIRFLOW_CTX_DAG_OWNER='***' AIRFLOW_CTX_DAG_ID='copy_tranform_to_mongo' AIRFLOW_CTX_TASK_ID='transform_data_by_pandas' AIRFLOW_CTX_EXECUTION_DATE='2021-05-04T00:00:00+00:00' AIRFLOW_CTX_TRY_NUMBER='1' AIRFLOW_CTX_DAG_RUN_ID='scheduled__2021-05-04T00:00:00+00:00'
[2023-10-18T11:17:43.429+0000] {taskinstance.py:1937} ERROR - Task failed with exception
Traceback (most recent call last):
  File "/home/airflow/.local/lib/python3.8/site-packages/urllib3/connectionpool.py", line 714, in urlopen
    httplib_response = self._make_request(
  File "/home/airflow/.local/lib/python3.8/site-packages/urllib3/connectionpool.py", line 415, in _make_request
    conn.request(method, url, **httplib_request_kw)
  File "/home/airflow/.local/lib/python3.8/site-packages/urllib3/connection.py", line 244, in request
    super(HTTPConnection, self).request(method, url, body=body, headers=headers)
  File "/usr/local/lib/python3.8/http/client.py", line 1256, in request
    self._send_request(method, url, body, headers, encode_chunked)
  File "/usr/local/lib/python3.8/http/client.py", line 1302, in _send_request
    self.endheaders(body, encode_chunked=encode_chunked)
  File "/usr/local/lib/python3.8/http/client.py", line 1251, in endheaders
    self._send_output(message_body, encode_chunked=encode_chunked)
  File "/usr/local/lib/python3.8/http/client.py", line 1011, in _send_output
    self.send(msg)
  File "/usr/local/lib/python3.8/http/client.py", line 951, in send
    self.connect()
  File "/home/airflow/.local/lib/python3.8/site-packages/docker/transport/unixconn.py", line 27, in connect
    sock.connect(self.unix_socket)
PermissionError: [Errno 13] Permission denied

During handling of the above exception, another exception occurred:

Traceback (most recent call last):
  File "/home/airflow/.local/lib/python3.8/site-packages/requests/adapters.py", line 486, in send
    resp = conn.urlopen(
  File "/home/airflow/.local/lib/python3.8/site-packages/urllib3/connectionpool.py", line 798, in urlopen
    retries = retries.increment(
  File "/home/airflow/.local/lib/python3.8/site-packages/urllib3/util/retry.py", line 550, in increment
    raise six.reraise(type(error), error, _stacktrace)
  File "/home/airflow/.local/lib/python3.8/site-packages/urllib3/packages/six.py", line 769, in reraise
    raise value.with_traceback(tb)
  File "/home/airflow/.local/lib/python3.8/site-packages/urllib3/connectionpool.py", line 714, in urlopen
    httplib_response = self._make_request(
  File "/home/airflow/.local/lib/python3.8/site-packages/urllib3/connectionpool.py", line 415, in _make_request
    conn.request(method, url, **httplib_request_kw)
  File "/home/airflow/.local/lib/python3.8/site-packages/urllib3/connection.py", line 244, in request
    super(HTTPConnection, self).request(method, url, body=body, headers=headers)
  File "/usr/local/lib/python3.8/http/client.py", line 1256, in request
    self._send_request(method, url, body, headers, encode_chunked)
  File "/usr/local/lib/python3.8/http/client.py", line 1302, in _send_request
    self.endheaders(body, encode_chunked=encode_chunked)
  File "/usr/local/lib/python3.8/http/client.py", line 1251, in endheaders
    self._send_output(message_body, encode_chunked=encode_chunked)
  File "/usr/local/lib/python3.8/http/client.py", line 1011, in _send_output
    self.send(msg)
  File "/usr/local/lib/python3.8/http/client.py", line 951, in send
    self.connect()
  File "/home/airflow/.local/lib/python3.8/site-packages/docker/transport/unixconn.py", line 27, in connect
    sock.connect(self.unix_socket)
urllib3.exceptions.ProtocolError: ('Connection aborted.', PermissionError(13, 'Permission denied'))

During handling of the above exception, another exception occurred:

Traceback (most recent call last):
  File "/home/airflow/.local/lib/python3.8/site-packages/docker/api/client.py", line 214, in _retrieve_server_version
    return self.version(api_version=False)["ApiVersion"]
  File "/home/airflow/.local/lib/python3.8/site-packages/docker/api/daemon.py", line 181, in version
    return self._result(self._get(url), json=True)
  File "/home/airflow/.local/lib/python3.8/site-packages/docker/utils/decorators.py", line 46, in inner
    return f(self, *args, **kwargs)
  File "/home/airflow/.local/lib/python3.8/site-packages/docker/api/client.py", line 237, in _get
    return self.get(url, **self._set_request_timeout(kwargs))
  File "/home/airflow/.local/lib/python3.8/site-packages/requests/sessions.py", line 602, in get
    return self.request("GET", url, **kwargs)
  File "/home/airflow/.local/lib/python3.8/site-packages/requests/sessions.py", line 589, in request
    resp = self.send(prep, **send_kwargs)
  File "/home/airflow/.local/lib/python3.8/site-packages/requests/sessions.py", line 703, in send
    r = adapter.send(request, **kwargs)
  File "/home/airflow/.local/lib/python3.8/site-packages/requests/adapters.py", line 501, in send
    raise ConnectionError(err, request=request)
requests.exceptions.ConnectionError: ('Connection aborted.', PermissionError(13, 'Permission denied'))

During handling of the above exception, another exception occurred:

Traceback (most recent call last):
  File "/home/airflow/.local/lib/python3.8/site-packages/airflow/providers/docker/operators/docker.py", line 462, in execute
    if self.force_pull or not self.cli.images(name=self.image):
  File "/home/airflow/.local/lib/python3.8/site-packages/airflow/providers/docker/operators/docker.py", line 333, in cli
    return self.hook.api_client
  File "/usr/local/lib/python3.8/functools.py", line 967, in __get__
    val = self.func(instance)
  File "/home/airflow/.local/lib/python3.8/site-packages/airflow/providers/docker/hooks/docker.py", line 120, in api_client
    client = APIClient(
  File "/home/airflow/.local/lib/python3.8/site-packages/docker/api/client.py", line 197, in __init__
    self._version = self._retrieve_server_version()
  File "/home/airflow/.local/lib/python3.8/site-packages/docker/api/client.py", line 221, in _retrieve_server_version
    raise DockerException(
docker.errors.DockerException: Error while fetching server API version: ('Connection aborted.', PermissionError(13, 'Permission denied'))
[2023-10-18T11:17:43.439+0000] {taskinstance.py:1400} INFO - Marking task as FAILED. dag_id=copy_tranform_to_mongo, task_id=transform_data_by_pandas, execution_date=20210504T000000, start_date=20231018T111743, end_date=20231018T111743
[2023-10-18T11:17:43.449+0000] {standard_task_runner.py:104} ERROR - Failed to execute job 214 for task transform_data_by_pandas (Error while fetching server API version: ('Connection aborted.', PermissionError(13, 'Permission denied')); 568)
[2023-10-18T11:17:43.487+0000] {local_task_job_runner.py:228} INFO - Task exited with return code 1
[2023-10-18T11:17:43.504+0000] {taskinstance.py:2778} INFO - 0 downstream tasks scheduled from follow-on schedule check
[2023-10-19T12:43:11.356+0000] {taskinstance.py:1159} INFO - Dependencies all met for dep_context=non-requeueable deps ti=<TaskInstance: copy_tranform_to_mongo.transform_data_by_pandas scheduled__2021-05-04T00:00:00+00:00 [queued]>
[2023-10-19T12:43:11.480+0000] {taskinstance.py:1159} INFO - Dependencies all met for dep_context=requeueable deps ti=<TaskInstance: copy_tranform_to_mongo.transform_data_by_pandas scheduled__2021-05-04T00:00:00+00:00 [queued]>
[2023-10-19T12:43:11.493+0000] {taskinstance.py:1361} INFO - Starting attempt 1 of 1
[2023-10-19T12:43:11.810+0000] {taskinstance.py:1382} INFO - Executing <Task(DockerOperator): transform_data_by_pandas> on 2021-05-04 00:00:00+00:00
[2023-10-19T12:43:11.832+0000] {standard_task_runner.py:57} INFO - Started process 1124 to run task
[2023-10-19T12:43:11.855+0000] {standard_task_runner.py:84} INFO - Running: ['***', 'tasks', 'run', 'copy_tranform_to_mongo', 'transform_data_by_pandas', 'scheduled__2021-05-04T00:00:00+00:00', '--job-id', '233', '--raw', '--subdir', 'DAGS_FOLDER/file_***-mongo.py', '--cfg-path', '/tmp/tmpvbe5sj3c']
[2023-10-19T12:43:11.866+0000] {standard_task_runner.py:85} INFO - Job 233: Subtask transform_data_by_pandas
[2023-10-19T12:43:12.309+0000] {task_command.py:416} INFO - Running <TaskInstance: copy_tranform_to_mongo.transform_data_by_pandas scheduled__2021-05-04T00:00:00+00:00 [running]> on host 6f5df7fea6fd
[2023-10-19T12:43:12.873+0000] {taskinstance.py:1662} INFO - Exporting env vars: AIRFLOW_CTX_DAG_OWNER='***' AIRFLOW_CTX_DAG_ID='copy_tranform_to_mongo' AIRFLOW_CTX_TASK_ID='transform_data_by_pandas' AIRFLOW_CTX_EXECUTION_DATE='2021-05-04T00:00:00+00:00' AIRFLOW_CTX_TRY_NUMBER='1' AIRFLOW_CTX_DAG_RUN_ID='scheduled__2021-05-04T00:00:00+00:00'
[2023-10-19T12:43:12.986+0000] {docker.py:337} INFO - Starting docker container from image python/pandas:1.0.0
[2023-10-19T12:43:15.632+0000] {docker.py:406} INFO - Input Notebook:  /opt/pandasapp/notebooks/tiktok_google_reviews.ipynb
[2023-10-19T12:43:15.632+0000] {docker.py:406} INFO - Output Notebook: /opt/pandasapp/notebooks/tiktok_google_reviews.ipynb
[2023-10-19T12:43:15.814+0000] {docker.py:406} INFO - Executing:   0%|          | 0/27 [00:00<?, ?cell/s]
[2023-10-19T12:43:20.728+0000] {docker.py:406} INFO - Executing notebook with kernel: python3
[2023-10-19T12:43:20.789+0000] {docker.py:406} INFO - Executing:   4%|▎         | 1/27 [00:04<02:09,  4.97s/cell]
[2023-10-19T12:43:20.953+0000] {docker.py:406} INFO - Executing:   7%|▋         | 2/27 [00:05<00:53,  2.14s/cell]
[2023-10-19T12:43:24.857+0000] {docker.py:406} INFO - Executing:  15%|█▍        | 4/27 [00:09<00:46,  2.02s/cell]
[2023-10-19T12:43:35.065+0000] {docker.py:406} INFO - Executing:  22%|██▏       | 6/27 [00:19<01:13,  3.48s/cell]
[2023-10-19T12:43:35.221+0000] {docker.py:406} INFO - Executing:  33%|███▎      | 9/27 [00:19<00:31,  1.75s/cell]
[2023-10-19T12:43:35.345+0000] {docker.py:406} INFO - Executing:  37%|███▋      | 10/27 [00:19<00:24,  1.44s/cell]
[2023-10-19T12:43:35.513+0000] {docker.py:406} INFO - Executing:  41%|████      | 11/27 [00:19<00:18,  1.16s/cell]
[2023-10-19T12:43:36.209+0000] {docker.py:406} INFO - Executing:  44%|████▍     | 12/27 [00:20<00:15,  1.06s/cell]
[2023-10-19T12:43:36.477+0000] {docker.py:406} INFO - Executing:  48%|████▊     | 13/27 [00:20<00:11,  1.17cell/s]
[2023-10-19T12:43:36.586+0000] {docker.py:406} INFO - Executing:  56%|█████▌    | 15/27 [00:20<00:06,  1.92cell/s]
[2023-10-19T12:43:37.369+0000] {docker.py:406} INFO - Executing:  59%|█████▉    | 16/27 [00:21<00:06,  1.73cell/s]
[2023-10-19T12:43:39.378+0000] {docker.py:406} INFO - Executing:  63%|██████▎   | 17/27 [00:23<00:09,  1.07cell/s]
[2023-10-19T12:43:39.686+0000] {docker.py:406} INFO - Executing:  70%|███████   | 19/27 [00:23<00:04,  1.63cell/s]
[2023-10-19T12:43:40.725+0000] {docker.py:406} INFO - Executing:  74%|███████▍  | 20/27 [00:24<00:04,  1.41cell/s]
[2023-10-19T12:43:41.693+0000] {docker.py:406} INFO - Executing:  78%|███████▊  | 21/27 [00:25<00:04,  1.30cell/s]
[2023-10-19T12:43:42.420+0000] {docker.py:406} INFO - Executing:  81%|████████▏ | 22/27 [00:26<00:03,  1.31cell/s]
[2023-10-19T12:43:43.223+0000] {docker.py:406} INFO - Executing:  85%|████████▌ | 23/27 [00:27<00:03,  1.29cell/s]
[2023-10-19T12:43:43.463+0000] {docker.py:406} INFO - Executing:  93%|█████████▎| 25/27 [00:27<00:00,  2.05cell/s]
[2023-10-19T12:43:45.716+0000] {docker.py:406} INFO - Executing:  96%|█████████▋| 26/27 [00:29<00:00,  1.10cell/s]
[2023-10-19T12:43:46.677+0000] {docker.py:406} INFO - Executing: 100%|██████████| 27/27 [00:30<00:00,  1.14s/cell]
[2023-10-19T12:43:47.285+0000] {taskinstance.py:1400} INFO - Marking task as SUCCESS. dag_id=copy_tranform_to_mongo, task_id=transform_data_by_pandas, execution_date=20210504T000000, start_date=20231019T124311, end_date=20231019T124347
[2023-10-19T12:43:47.338+0000] {local_task_job_runner.py:228} INFO - Task exited with return code 0
[2023-10-19T12:43:47.375+0000] {taskinstance.py:2778} INFO - 1 downstream tasks scheduled from follow-on schedule check
