[2023-10-18T11:17:32.006+0000] {taskinstance.py:1159} INFO - Dependencies all met for dep_context=non-requeueable deps ti=<TaskInstance: copy_tranform_to_mongo.transform_data_by_pandas scheduled__2021-04-16T00:00:00+00:00 [queued]>
[2023-10-18T11:17:32.021+0000] {taskinstance.py:1159} INFO - Dependencies all met for dep_context=requeueable deps ti=<TaskInstance: copy_tranform_to_mongo.transform_data_by_pandas scheduled__2021-04-16T00:00:00+00:00 [queued]>
[2023-10-18T11:17:32.022+0000] {taskinstance.py:1361} INFO - Starting attempt 1 of 1
[2023-10-18T11:17:32.040+0000] {taskinstance.py:1382} INFO - Executing <Task(DockerOperator): transform_data_by_pandas> on 2021-04-16 00:00:00+00:00
[2023-10-18T11:17:32.051+0000] {standard_task_runner.py:57} INFO - Started process 488 to run task
[2023-10-18T11:17:32.058+0000] {standard_task_runner.py:84} INFO - Running: ['***', 'tasks', 'run', 'copy_tranform_to_mongo', 'transform_data_by_pandas', 'scheduled__2021-04-16T00:00:00+00:00', '--job-id', '178', '--raw', '--subdir', 'DAGS_FOLDER/file_***-mongo.py', '--cfg-path', '/tmp/tmp70b5jrux']
[2023-10-18T11:17:32.059+0000] {standard_task_runner.py:85} INFO - Job 178: Subtask transform_data_by_pandas
[2023-10-18T11:17:32.108+0000] {task_command.py:416} INFO - Running <TaskInstance: copy_tranform_to_mongo.transform_data_by_pandas scheduled__2021-04-16T00:00:00+00:00 [running]> on host 0e68aa52dfc7
[2023-10-18T11:17:32.184+0000] {taskinstance.py:1662} INFO - Exporting env vars: AIRFLOW_CTX_DAG_OWNER='***' AIRFLOW_CTX_DAG_ID='copy_tranform_to_mongo' AIRFLOW_CTX_TASK_ID='transform_data_by_pandas' AIRFLOW_CTX_EXECUTION_DATE='2021-04-16T00:00:00+00:00' AIRFLOW_CTX_TRY_NUMBER='1' AIRFLOW_CTX_DAG_RUN_ID='scheduled__2021-04-16T00:00:00+00:00'
[2023-10-18T11:17:32.189+0000] {taskinstance.py:1937} ERROR - Task failed with exception
Traceback (most recent call last):
  File "/home/airflow/.local/lib/python3.8/site-packages/urllib3/connectionpool.py", line 714, in urlopen
    httplib_response = self._make_request(
  File "/home/airflow/.local/lib/python3.8/site-packages/urllib3/connectionpool.py", line 415, in _make_request
    conn.request(method, url, **httplib_request_kw)
  File "/home/airflow/.local/lib/python3.8/site-packages/urllib3/connection.py", line 244, in request
    super(HTTPConnection, self).request(method, url, body=body, headers=headers)
  File "/usr/local/lib/python3.8/http/client.py", line 1256, in request
    self._send_request(method, url, body, headers, encode_chunked)
  File "/usr/local/lib/python3.8/http/client.py", line 1302, in _send_request
    self.endheaders(body, encode_chunked=encode_chunked)
  File "/usr/local/lib/python3.8/http/client.py", line 1251, in endheaders
    self._send_output(message_body, encode_chunked=encode_chunked)
  File "/usr/local/lib/python3.8/http/client.py", line 1011, in _send_output
    self.send(msg)
  File "/usr/local/lib/python3.8/http/client.py", line 951, in send
    self.connect()
  File "/home/airflow/.local/lib/python3.8/site-packages/docker/transport/unixconn.py", line 27, in connect
    sock.connect(self.unix_socket)
PermissionError: [Errno 13] Permission denied

During handling of the above exception, another exception occurred:

Traceback (most recent call last):
  File "/home/airflow/.local/lib/python3.8/site-packages/requests/adapters.py", line 486, in send
    resp = conn.urlopen(
  File "/home/airflow/.local/lib/python3.8/site-packages/urllib3/connectionpool.py", line 798, in urlopen
    retries = retries.increment(
  File "/home/airflow/.local/lib/python3.8/site-packages/urllib3/util/retry.py", line 550, in increment
    raise six.reraise(type(error), error, _stacktrace)
  File "/home/airflow/.local/lib/python3.8/site-packages/urllib3/packages/six.py", line 769, in reraise
    raise value.with_traceback(tb)
  File "/home/airflow/.local/lib/python3.8/site-packages/urllib3/connectionpool.py", line 714, in urlopen
    httplib_response = self._make_request(
  File "/home/airflow/.local/lib/python3.8/site-packages/urllib3/connectionpool.py", line 415, in _make_request
    conn.request(method, url, **httplib_request_kw)
  File "/home/airflow/.local/lib/python3.8/site-packages/urllib3/connection.py", line 244, in request
    super(HTTPConnection, self).request(method, url, body=body, headers=headers)
  File "/usr/local/lib/python3.8/http/client.py", line 1256, in request
    self._send_request(method, url, body, headers, encode_chunked)
  File "/usr/local/lib/python3.8/http/client.py", line 1302, in _send_request
    self.endheaders(body, encode_chunked=encode_chunked)
  File "/usr/local/lib/python3.8/http/client.py", line 1251, in endheaders
    self._send_output(message_body, encode_chunked=encode_chunked)
  File "/usr/local/lib/python3.8/http/client.py", line 1011, in _send_output
    self.send(msg)
  File "/usr/local/lib/python3.8/http/client.py", line 951, in send
    self.connect()
  File "/home/airflow/.local/lib/python3.8/site-packages/docker/transport/unixconn.py", line 27, in connect
    sock.connect(self.unix_socket)
urllib3.exceptions.ProtocolError: ('Connection aborted.', PermissionError(13, 'Permission denied'))

During handling of the above exception, another exception occurred:

Traceback (most recent call last):
  File "/home/airflow/.local/lib/python3.8/site-packages/docker/api/client.py", line 214, in _retrieve_server_version
    return self.version(api_version=False)["ApiVersion"]
  File "/home/airflow/.local/lib/python3.8/site-packages/docker/api/daemon.py", line 181, in version
    return self._result(self._get(url), json=True)
  File "/home/airflow/.local/lib/python3.8/site-packages/docker/utils/decorators.py", line 46, in inner
    return f(self, *args, **kwargs)
  File "/home/airflow/.local/lib/python3.8/site-packages/docker/api/client.py", line 237, in _get
    return self.get(url, **self._set_request_timeout(kwargs))
  File "/home/airflow/.local/lib/python3.8/site-packages/requests/sessions.py", line 602, in get
    return self.request("GET", url, **kwargs)
  File "/home/airflow/.local/lib/python3.8/site-packages/requests/sessions.py", line 589, in request
    resp = self.send(prep, **send_kwargs)
  File "/home/airflow/.local/lib/python3.8/site-packages/requests/sessions.py", line 703, in send
    r = adapter.send(request, **kwargs)
  File "/home/airflow/.local/lib/python3.8/site-packages/requests/adapters.py", line 501, in send
    raise ConnectionError(err, request=request)
requests.exceptions.ConnectionError: ('Connection aborted.', PermissionError(13, 'Permission denied'))

During handling of the above exception, another exception occurred:

Traceback (most recent call last):
  File "/home/airflow/.local/lib/python3.8/site-packages/airflow/providers/docker/operators/docker.py", line 462, in execute
    if self.force_pull or not self.cli.images(name=self.image):
  File "/home/airflow/.local/lib/python3.8/site-packages/airflow/providers/docker/operators/docker.py", line 333, in cli
    return self.hook.api_client
  File "/usr/local/lib/python3.8/functools.py", line 967, in __get__
    val = self.func(instance)
  File "/home/airflow/.local/lib/python3.8/site-packages/airflow/providers/docker/hooks/docker.py", line 120, in api_client
    client = APIClient(
  File "/home/airflow/.local/lib/python3.8/site-packages/docker/api/client.py", line 197, in __init__
    self._version = self._retrieve_server_version()
  File "/home/airflow/.local/lib/python3.8/site-packages/docker/api/client.py", line 221, in _retrieve_server_version
    raise DockerException(
docker.errors.DockerException: Error while fetching server API version: ('Connection aborted.', PermissionError(13, 'Permission denied'))
[2023-10-18T11:17:32.200+0000] {taskinstance.py:1400} INFO - Marking task as FAILED. dag_id=copy_tranform_to_mongo, task_id=transform_data_by_pandas, execution_date=20210416T000000, start_date=20231018T111732, end_date=20231018T111732
[2023-10-18T11:17:32.213+0000] {standard_task_runner.py:104} ERROR - Failed to execute job 178 for task transform_data_by_pandas (Error while fetching server API version: ('Connection aborted.', PermissionError(13, 'Permission denied')); 488)
[2023-10-18T11:17:32.228+0000] {local_task_job_runner.py:228} INFO - Task exited with return code 1
[2023-10-18T11:17:32.278+0000] {taskinstance.py:2778} INFO - 0 downstream tasks scheduled from follow-on schedule check
[2023-10-19T12:22:14.887+0000] {taskinstance.py:1159} INFO - Dependencies all met for dep_context=non-requeueable deps ti=<TaskInstance: copy_tranform_to_mongo.transform_data_by_pandas scheduled__2021-04-16T00:00:00+00:00 [queued]>
[2023-10-19T12:22:14.953+0000] {taskinstance.py:1159} INFO - Dependencies all met for dep_context=requeueable deps ti=<TaskInstance: copy_tranform_to_mongo.transform_data_by_pandas scheduled__2021-04-16T00:00:00+00:00 [queued]>
[2023-10-19T12:22:14.954+0000] {taskinstance.py:1361} INFO - Starting attempt 1 of 1
[2023-10-19T12:22:15.013+0000] {taskinstance.py:1382} INFO - Executing <Task(DockerOperator): transform_data_by_pandas> on 2021-04-16 00:00:00+00:00
[2023-10-19T12:22:15.029+0000] {standard_task_runner.py:57} INFO - Started process 700 to run task
[2023-10-19T12:22:15.034+0000] {standard_task_runner.py:84} INFO - Running: ['***', 'tasks', 'run', 'copy_tranform_to_mongo', 'transform_data_by_pandas', 'scheduled__2021-04-16T00:00:00+00:00', '--job-id', '177', '--raw', '--subdir', 'DAGS_FOLDER/file_***-mongo.py', '--cfg-path', '/tmp/tmp47bdxk3x']
[2023-10-19T12:22:15.042+0000] {standard_task_runner.py:85} INFO - Job 177: Subtask transform_data_by_pandas
[2023-10-19T12:22:15.154+0000] {task_command.py:416} INFO - Running <TaskInstance: copy_tranform_to_mongo.transform_data_by_pandas scheduled__2021-04-16T00:00:00+00:00 [running]> on host 6f5df7fea6fd
[2023-10-19T12:22:15.345+0000] {taskinstance.py:1662} INFO - Exporting env vars: AIRFLOW_CTX_DAG_OWNER='***' AIRFLOW_CTX_DAG_ID='copy_tranform_to_mongo' AIRFLOW_CTX_TASK_ID='transform_data_by_pandas' AIRFLOW_CTX_EXECUTION_DATE='2021-04-16T00:00:00+00:00' AIRFLOW_CTX_TRY_NUMBER='1' AIRFLOW_CTX_DAG_RUN_ID='scheduled__2021-04-16T00:00:00+00:00'
[2023-10-19T12:22:15.438+0000] {docker.py:337} INFO - Starting docker container from image python/pandas:1.0.0
[2023-10-19T12:22:16.604+0000] {docker.py:406} INFO - Input Notebook:  /opt/pandasapp/notebooks/tiktok_google_reviews.ipynb
Output Notebook: /opt/pandasapp/notebooks/tiktok_google_reviews.ipynb
[2023-10-19T12:22:16.766+0000] {docker.py:406} INFO - Executing:   0%|          | 0/27 [00:00<?, ?cell/s]
[2023-10-19T12:22:18.593+0000] {docker.py:406} INFO - Executing notebook with kernel: python3
[2023-10-19T12:22:18.621+0000] {docker.py:406} INFO - Executing:   4%|▎         | 1/27 [00:01<00:48,  1.85s/cell]
[2023-10-19T12:22:18.728+0000] {docker.py:406} INFO - Executing:  11%|█         | 3/27 [00:01<00:12,  1.92cell/s]
[2023-10-19T12:22:21.207+0000] {docker.py:406} INFO - Executing:  19%|█▊        | 5/27 [00:04<00:19,  1.12cell/s]
[2023-10-19T12:22:24.539+0000] {docker.py:406} INFO - Executing:  22%|██▏       | 6/27 [00:07<00:32,  1.55s/cell]
[2023-10-19T12:22:24.817+0000] {docker.py:406} INFO - Executing:  33%|███▎      | 9/27 [00:08<00:13,  1.30cell/s]
[2023-10-19T12:22:25.020+0000] {docker.py:406} INFO - Executing:  37%|███▋      | 10/27 [00:08<00:11,  1.53cell/s]
[2023-10-19T12:22:25.189+0000] {docker.py:406} INFO - Executing:  41%|████      | 11/27 [00:08<00:08,  1.84cell/s]
[2023-10-19T12:22:25.806+0000] {docker.py:406} INFO - Executing:  44%|████▍     | 12/27 [00:09<00:08,  1.78cell/s]
[2023-10-19T12:22:26.073+0000] {docker.py:406} INFO - Executing:  48%|████▊     | 13/27 [00:09<00:06,  2.06cell/s]
[2023-10-19T12:22:26.187+0000] {docker.py:406} INFO - Executing:  56%|█████▌    | 15/27 [00:09<00:03,  3.29cell/s]
[2023-10-19T12:22:27.434+0000] {docker.py:406} INFO - Executing:  59%|█████▉    | 16/27 [00:10<00:05,  1.91cell/s]
[2023-10-19T12:22:29.694+0000] {docker.py:406} INFO - Executing:  63%|██████▎   | 17/27 [00:12<00:09,  1.05cell/s]
[2023-10-19T12:22:30.122+0000] {docker.py:406} INFO - Executing:  70%|███████   | 19/27 [00:13<00:05,  1.54cell/s]
[2023-10-19T12:22:31.580+0000] {docker.py:406} INFO - Executing:  74%|███████▍  | 20/27 [00:14<00:05,  1.20cell/s]
[2023-10-19T12:22:32.965+0000] {docker.py:406} INFO - Executing:  78%|███████▊  | 21/27 [00:16<00:05,  1.03cell/s]
[2023-10-19T12:22:34.910+0000] {docker.py:406} INFO - Executing:  81%|████████▏ | 22/27 [00:18<00:06,  1.22s/cell]
[2023-10-19T12:22:37.078+0000] {docker.py:406} INFO - Executing:  85%|████████▌ | 23/27 [00:20<00:05,  1.48s/cell]
[2023-10-19T12:22:37.201+0000] {docker.py:406} INFO - Executing:  89%|████████▉ | 24/27 [00:20<00:03,  1.10s/cell]
[2023-10-19T12:22:37.493+0000] {docker.py:406} INFO - Executing:  93%|█████████▎| 25/27 [00:20<00:01,  1.15cell/s]
[2023-10-19T12:22:43.547+0000] {docker.py:406} INFO - Executing:  96%|█████████▋| 26/27 [00:26<00:02,  2.37s/cell]
[2023-10-19T12:22:46.631+0000] {docker.py:406} INFO - Executing: 100%|██████████| 27/27 [00:29<00:00,  1.11s/cell]
[2023-10-19T12:22:46.633+0000] {docker.py:406} INFO - 
[2023-10-19T12:22:48.056+0000] {taskinstance.py:1400} INFO - Marking task as SUCCESS. dag_id=copy_tranform_to_mongo, task_id=transform_data_by_pandas, execution_date=20210416T000000, start_date=20231019T122214, end_date=20231019T122248
[2023-10-19T12:22:48.202+0000] {local_task_job_runner.py:228} INFO - Task exited with return code 0
[2023-10-19T12:22:48.361+0000] {taskinstance.py:2778} INFO - 1 downstream tasks scheduled from follow-on schedule check
