[2023-10-17T11:18:54.982+0000] {taskinstance.py:1159} INFO - Dependencies all met for dep_context=non-requeueable deps ti=<TaskInstance: copy_tranform_to_mongo.waiting_for_data scheduled__2021-02-02T00:00:00+00:00 [queued]>
[2023-10-17T11:18:54.991+0000] {taskinstance.py:1159} INFO - Dependencies all met for dep_context=requeueable deps ti=<TaskInstance: copy_tranform_to_mongo.waiting_for_data scheduled__2021-02-02T00:00:00+00:00 [queued]>
[2023-10-17T11:18:54.991+0000] {taskinstance.py:1361} INFO - Starting attempt 1 of 1
[2023-10-17T11:18:55.000+0000] {taskinstance.py:1382} INFO - Executing <Task(FileSensor): waiting_for_data> on 2021-02-02 00:00:00+00:00
[2023-10-17T11:18:55.007+0000] {standard_task_runner.py:57} INFO - Started process 490 to run task
[2023-10-17T11:18:55.009+0000] {standard_task_runner.py:84} INFO - Running: ['***', 'tasks', 'run', 'copy_tranform_to_mongo', 'waiting_for_data', 'scheduled__2021-02-02T00:00:00+00:00', '--job-id', '37', '--raw', '--subdir', 'DAGS_FOLDER/file_***-mongo.py', '--cfg-path', '/tmp/tmpghxxsosx']
[2023-10-17T11:18:55.010+0000] {standard_task_runner.py:85} INFO - Job 37: Subtask waiting_for_data
[2023-10-17T11:18:55.047+0000] {task_command.py:416} INFO - Running <TaskInstance: copy_tranform_to_mongo.waiting_for_data scheduled__2021-02-02T00:00:00+00:00 [running]> on host 238c1d4ff767
[2023-10-17T11:18:55.106+0000] {taskinstance.py:1662} INFO - Exporting env vars: AIRFLOW_CTX_DAG_OWNER='***' AIRFLOW_CTX_DAG_ID='copy_tranform_to_mongo' AIRFLOW_CTX_TASK_ID='waiting_for_data' AIRFLOW_CTX_EXECUTION_DATE='2021-02-02T00:00:00+00:00' AIRFLOW_CTX_TRY_NUMBER='1' AIRFLOW_CTX_DAG_RUN_ID='scheduled__2021-02-02T00:00:00+00:00'
[2023-10-17T11:18:55.113+0000] {base.py:73} INFO - Using connection ID 'fs_default' for task execution.
[2023-10-17T11:18:55.113+0000] {filesystem.py:64} INFO - Poking for file /opt/in/tiktok_google_play_reviews.csv
[2023-10-17T11:18:55.114+0000] {filesystem.py:69} INFO - Found File /opt/in/tiktok_google_play_reviews.csv last modified: 20220405221612
[2023-10-17T11:18:55.114+0000] {base.py:287} INFO - Success criteria met. Exiting.
[2023-10-17T11:18:55.120+0000] {taskinstance.py:1400} INFO - Marking task as SUCCESS. dag_id=copy_tranform_to_mongo, task_id=waiting_for_data, execution_date=20210202T000000, start_date=20231017T111854, end_date=20231017T111855
[2023-10-17T11:18:55.141+0000] {local_task_job_runner.py:228} INFO - Task exited with return code 0
[2023-10-17T11:18:55.153+0000] {taskinstance.py:2778} INFO - 0 downstream tasks scheduled from follow-on schedule check
[2023-10-18T10:42:23.217+0000] {taskinstance.py:1159} INFO - Dependencies all met for dep_context=non-requeueable deps ti=<TaskInstance: copy_tranform_to_mongo.waiting_for_data scheduled__2021-02-02T00:00:00+00:00 [queued]>
[2023-10-18T10:42:23.227+0000] {taskinstance.py:1159} INFO - Dependencies all met for dep_context=requeueable deps ti=<TaskInstance: copy_tranform_to_mongo.waiting_for_data scheduled__2021-02-02T00:00:00+00:00 [queued]>
[2023-10-18T10:42:23.228+0000] {taskinstance.py:1361} INFO - Starting attempt 1 of 1
[2023-10-18T10:42:23.244+0000] {taskinstance.py:1382} INFO - Executing <Task(FileSensor): waiting_for_data> on 2021-02-02 00:00:00+00:00
[2023-10-18T10:42:23.253+0000] {standard_task_runner.py:57} INFO - Started process 1454 to run task
[2023-10-18T10:42:23.256+0000] {standard_task_runner.py:84} INFO - Running: ['***', 'tasks', 'run', 'copy_tranform_to_mongo', 'waiting_for_data', 'scheduled__2021-02-02T00:00:00+00:00', '--job-id', '36', '--raw', '--subdir', 'DAGS_FOLDER/file_***-mongo.py', '--cfg-path', '/tmp/tmp4oby6sv5']
[2023-10-18T10:42:23.257+0000] {standard_task_runner.py:85} INFO - Job 36: Subtask waiting_for_data
[2023-10-18T10:42:23.312+0000] {task_command.py:416} INFO - Running <TaskInstance: copy_tranform_to_mongo.waiting_for_data scheduled__2021-02-02T00:00:00+00:00 [running]> on host 2473b23ba069
[2023-10-18T10:42:23.381+0000] {taskinstance.py:1662} INFO - Exporting env vars: AIRFLOW_CTX_DAG_OWNER='***' AIRFLOW_CTX_DAG_ID='copy_tranform_to_mongo' AIRFLOW_CTX_TASK_ID='waiting_for_data' AIRFLOW_CTX_EXECUTION_DATE='2021-02-02T00:00:00+00:00' AIRFLOW_CTX_TRY_NUMBER='1' AIRFLOW_CTX_DAG_RUN_ID='scheduled__2021-02-02T00:00:00+00:00'
[2023-10-18T10:42:23.397+0000] {taskinstance.py:1937} ERROR - Task failed with exception
Traceback (most recent call last):
  File "/home/airflow/.local/lib/python3.8/site-packages/airflow/sensors/base.py", line 257, in execute
    raise e
  File "/home/airflow/.local/lib/python3.8/site-packages/airflow/sensors/base.py", line 239, in execute
    poke_return = self.poke(context)
  File "/home/airflow/.local/lib/python3.8/site-packages/airflow/sensors/filesystem.py", line 61, in poke
    hook = FSHook(self.fs_conn_id)
  File "/home/airflow/.local/lib/python3.8/site-packages/airflow/hooks/filesystem.py", line 38, in __init__
    conn = self.get_connection(conn_id)
  File "/home/airflow/.local/lib/python3.8/site-packages/airflow/hooks/base.py", line 72, in get_connection
    conn = Connection.get_connection_from_secrets(conn_id)
  File "/home/airflow/.local/lib/python3.8/site-packages/airflow/models/connection.py", line 477, in get_connection_from_secrets
    raise AirflowNotFoundException(f"The conn_id `{conn_id}` isn't defined")
airflow.exceptions.AirflowNotFoundException: The conn_id `fs_default` isn't defined
[2023-10-18T10:42:23.401+0000] {taskinstance.py:1400} INFO - Marking task as FAILED. dag_id=copy_tranform_to_mongo, task_id=waiting_for_data, execution_date=20210202T000000, start_date=20231018T104223, end_date=20231018T104223
[2023-10-18T10:42:23.415+0000] {standard_task_runner.py:104} ERROR - Failed to execute job 36 for task waiting_for_data (The conn_id `fs_default` isn't defined; 1454)
[2023-10-18T10:42:23.434+0000] {local_task_job_runner.py:228} INFO - Task exited with return code 1
[2023-10-18T10:42:23.473+0000] {taskinstance.py:2778} INFO - 0 downstream tasks scheduled from follow-on schedule check
[2023-10-18T11:14:54.025+0000] {taskinstance.py:1159} INFO - Dependencies all met for dep_context=non-requeueable deps ti=<TaskInstance: copy_tranform_to_mongo.waiting_for_data scheduled__2021-02-02T00:00:00+00:00 [queued]>
[2023-10-18T11:14:54.037+0000] {taskinstance.py:1159} INFO - Dependencies all met for dep_context=requeueable deps ti=<TaskInstance: copy_tranform_to_mongo.waiting_for_data scheduled__2021-02-02T00:00:00+00:00 [queued]>
[2023-10-18T11:14:54.037+0000] {taskinstance.py:1361} INFO - Starting attempt 1 of 1
[2023-10-18T11:14:54.060+0000] {taskinstance.py:1382} INFO - Executing <Task(FileSensor): waiting_for_data> on 2021-02-02 00:00:00+00:00
[2023-10-18T11:14:54.068+0000] {standard_task_runner.py:57} INFO - Started process 161 to run task
[2023-10-18T11:14:54.073+0000] {standard_task_runner.py:84} INFO - Running: ['***', 'tasks', 'run', 'copy_tranform_to_mongo', 'waiting_for_data', 'scheduled__2021-02-02T00:00:00+00:00', '--job-id', '35', '--raw', '--subdir', 'DAGS_FOLDER/file_***-mongo.py', '--cfg-path', '/tmp/tmpib20i5wd']
[2023-10-18T11:14:54.075+0000] {standard_task_runner.py:85} INFO - Job 35: Subtask waiting_for_data
[2023-10-18T11:14:54.126+0000] {task_command.py:416} INFO - Running <TaskInstance: copy_tranform_to_mongo.waiting_for_data scheduled__2021-02-02T00:00:00+00:00 [running]> on host 0e68aa52dfc7
[2023-10-18T11:14:54.197+0000] {taskinstance.py:1662} INFO - Exporting env vars: AIRFLOW_CTX_DAG_OWNER='***' AIRFLOW_CTX_DAG_ID='copy_tranform_to_mongo' AIRFLOW_CTX_TASK_ID='waiting_for_data' AIRFLOW_CTX_EXECUTION_DATE='2021-02-02T00:00:00+00:00' AIRFLOW_CTX_TRY_NUMBER='1' AIRFLOW_CTX_DAG_RUN_ID='scheduled__2021-02-02T00:00:00+00:00'
[2023-10-18T11:14:54.212+0000] {taskinstance.py:1937} ERROR - Task failed with exception
Traceback (most recent call last):
  File "/home/airflow/.local/lib/python3.8/site-packages/airflow/sensors/base.py", line 257, in execute
    raise e
  File "/home/airflow/.local/lib/python3.8/site-packages/airflow/sensors/base.py", line 239, in execute
    poke_return = self.poke(context)
  File "/home/airflow/.local/lib/python3.8/site-packages/airflow/sensors/filesystem.py", line 61, in poke
    hook = FSHook(self.fs_conn_id)
  File "/home/airflow/.local/lib/python3.8/site-packages/airflow/hooks/filesystem.py", line 38, in __init__
    conn = self.get_connection(conn_id)
  File "/home/airflow/.local/lib/python3.8/site-packages/airflow/hooks/base.py", line 72, in get_connection
    conn = Connection.get_connection_from_secrets(conn_id)
  File "/home/airflow/.local/lib/python3.8/site-packages/airflow/models/connection.py", line 477, in get_connection_from_secrets
    raise AirflowNotFoundException(f"The conn_id `{conn_id}` isn't defined")
airflow.exceptions.AirflowNotFoundException: The conn_id `fs_default` isn't defined
[2023-10-18T11:14:54.215+0000] {taskinstance.py:1400} INFO - Marking task as FAILED. dag_id=copy_tranform_to_mongo, task_id=waiting_for_data, execution_date=20210202T000000, start_date=20231018T111454, end_date=20231018T111454
[2023-10-18T11:14:54.229+0000] {standard_task_runner.py:104} ERROR - Failed to execute job 35 for task waiting_for_data (The conn_id `fs_default` isn't defined; 161)
[2023-10-18T11:14:54.248+0000] {local_task_job_runner.py:228} INFO - Task exited with return code 1
[2023-10-18T11:14:54.277+0000] {taskinstance.py:2778} INFO - 0 downstream tasks scheduled from follow-on schedule check
[2023-10-19T12:10:04.370+0000] {taskinstance.py:1159} INFO - Dependencies all met for dep_context=non-requeueable deps ti=<TaskInstance: copy_tranform_to_mongo.waiting_for_data scheduled__2021-02-02T00:00:00+00:00 [queued]>
[2023-10-19T12:10:04.379+0000] {taskinstance.py:1159} INFO - Dependencies all met for dep_context=requeueable deps ti=<TaskInstance: copy_tranform_to_mongo.waiting_for_data scheduled__2021-02-02T00:00:00+00:00 [queued]>
[2023-10-19T12:10:04.379+0000] {taskinstance.py:1361} INFO - Starting attempt 1 of 1
[2023-10-19T12:10:04.391+0000] {taskinstance.py:1382} INFO - Executing <Task(FileSensor): waiting_for_data> on 2021-02-02 00:00:00+00:00
[2023-10-19T12:10:04.397+0000] {standard_task_runner.py:57} INFO - Started process 232 to run task
[2023-10-19T12:10:04.399+0000] {standard_task_runner.py:84} INFO - Running: ['***', 'tasks', 'run', 'copy_tranform_to_mongo', 'waiting_for_data', 'scheduled__2021-02-02T00:00:00+00:00', '--job-id', '35', '--raw', '--subdir', 'DAGS_FOLDER/file_***-mongo.py', '--cfg-path', '/tmp/tmp3n0hi27d']
[2023-10-19T12:10:04.401+0000] {standard_task_runner.py:85} INFO - Job 35: Subtask waiting_for_data
[2023-10-19T12:10:04.444+0000] {task_command.py:416} INFO - Running <TaskInstance: copy_tranform_to_mongo.waiting_for_data scheduled__2021-02-02T00:00:00+00:00 [running]> on host 6f5df7fea6fd
[2023-10-19T12:10:04.517+0000] {taskinstance.py:1662} INFO - Exporting env vars: AIRFLOW_CTX_DAG_OWNER='***' AIRFLOW_CTX_DAG_ID='copy_tranform_to_mongo' AIRFLOW_CTX_TASK_ID='waiting_for_data' AIRFLOW_CTX_EXECUTION_DATE='2021-02-02T00:00:00+00:00' AIRFLOW_CTX_TRY_NUMBER='1' AIRFLOW_CTX_DAG_RUN_ID='scheduled__2021-02-02T00:00:00+00:00'
[2023-10-19T12:10:04.535+0000] {taskinstance.py:1937} ERROR - Task failed with exception
Traceback (most recent call last):
  File "/home/airflow/.local/lib/python3.8/site-packages/airflow/sensors/base.py", line 257, in execute
    raise e
  File "/home/airflow/.local/lib/python3.8/site-packages/airflow/sensors/base.py", line 239, in execute
    poke_return = self.poke(context)
  File "/home/airflow/.local/lib/python3.8/site-packages/airflow/sensors/filesystem.py", line 61, in poke
    hook = FSHook(self.fs_conn_id)
  File "/home/airflow/.local/lib/python3.8/site-packages/airflow/hooks/filesystem.py", line 38, in __init__
    conn = self.get_connection(conn_id)
  File "/home/airflow/.local/lib/python3.8/site-packages/airflow/hooks/base.py", line 72, in get_connection
    conn = Connection.get_connection_from_secrets(conn_id)
  File "/home/airflow/.local/lib/python3.8/site-packages/airflow/models/connection.py", line 477, in get_connection_from_secrets
    raise AirflowNotFoundException(f"The conn_id `{conn_id}` isn't defined")
airflow.exceptions.AirflowNotFoundException: The conn_id `fs_default` isn't defined
[2023-10-19T12:10:04.539+0000] {taskinstance.py:1400} INFO - Marking task as FAILED. dag_id=copy_tranform_to_mongo, task_id=waiting_for_data, execution_date=20210202T000000, start_date=20231019T121004, end_date=20231019T121004
[2023-10-19T12:10:04.548+0000] {standard_task_runner.py:104} ERROR - Failed to execute job 35 for task waiting_for_data (The conn_id `fs_default` isn't defined; 232)
[2023-10-19T12:10:04.571+0000] {local_task_job_runner.py:228} INFO - Task exited with return code 1
[2023-10-19T12:10:04.604+0000] {taskinstance.py:2778} INFO - 0 downstream tasks scheduled from follow-on schedule check
