[2023-10-19T12:22:51.641+0000] {taskinstance.py:1159} INFO - Dependencies all met for dep_context=non-requeueable deps ti=<TaskInstance: copy_tranform_to_mongo.load_data_to_mongo scheduled__2021-04-12T00:00:00+00:00 [queued]>
[2023-10-19T12:22:51.672+0000] {taskinstance.py:1159} INFO - Dependencies all met for dep_context=requeueable deps ti=<TaskInstance: copy_tranform_to_mongo.load_data_to_mongo scheduled__2021-04-12T00:00:00+00:00 [queued]>
[2023-10-19T12:22:51.673+0000] {taskinstance.py:1361} INFO - Starting attempt 1 of 1
[2023-10-19T12:22:51.721+0000] {taskinstance.py:1382} INFO - Executing <Task(DockerOperator): load_data_to_mongo> on 2021-04-12 00:00:00+00:00
[2023-10-19T12:22:51.751+0000] {standard_task_runner.py:57} INFO - Started process 728 to run task
[2023-10-19T12:22:51.755+0000] {standard_task_runner.py:84} INFO - Running: ['***', 'tasks', 'run', 'copy_tranform_to_mongo', 'load_data_to_mongo', 'scheduled__2021-04-12T00:00:00+00:00', '--job-id', '187', '--raw', '--subdir', 'DAGS_FOLDER/file_***-mongo.py', '--cfg-path', '/tmp/tmp9i099l7b']
[2023-10-19T12:22:51.756+0000] {standard_task_runner.py:85} INFO - Job 187: Subtask load_data_to_mongo
[2023-10-19T12:22:52.068+0000] {task_command.py:416} INFO - Running <TaskInstance: copy_tranform_to_mongo.load_data_to_mongo scheduled__2021-04-12T00:00:00+00:00 [running]> on host 6f5df7fea6fd
[2023-10-19T12:22:52.444+0000] {taskinstance.py:1662} INFO - Exporting env vars: AIRFLOW_CTX_DAG_OWNER='***' AIRFLOW_CTX_DAG_ID='copy_tranform_to_mongo' AIRFLOW_CTX_TASK_ID='load_data_to_mongo' AIRFLOW_CTX_EXECUTION_DATE='2021-04-12T00:00:00+00:00' AIRFLOW_CTX_TRY_NUMBER='1' AIRFLOW_CTX_DAG_RUN_ID='scheduled__2021-04-12T00:00:00+00:00'
[2023-10-19T12:22:52.542+0000] {docker.py:337} INFO - Starting docker container from image python/pandas:1.0.0
[2023-10-19T12:23:27.115+0000] {docker.py:406} INFO - Traceback (most recent call last):
  File "/opt/pandasapp/script/load_to_mongo.py", line 27, in <module>
[2023-10-19T12:23:27.115+0000] {docker.py:406} INFO - collection.insert_one(doc_to_insert)
  File "/usr/local/lib/python3.10/site-packages/pymongo/collection.py", line 671, in insert_one
[2023-10-19T12:23:27.115+0000] {docker.py:406} INFO - self._insert_one(
  File "/usr/local/lib/python3.10/site-packages/pymongo/collection.py", line 611, in _insert_one
[2023-10-19T12:23:27.116+0000] {docker.py:406} INFO - self.__database.client._retryable_write(acknowledged, _insert_command, session)
  File "/usr/local/lib/python3.10/site-packages/pymongo/mongo_client.py", line 1567, in _retryable_write
[2023-10-19T12:23:27.116+0000] {docker.py:406} INFO - with self._tmp_session(session) as s:
  File "/usr/local/lib/python3.10/contextlib.py", line 135, in __enter__
[2023-10-19T12:23:27.116+0000] {docker.py:406} INFO - return next(self.gen)
  File "/usr/local/lib/python3.10/site-packages/pymongo/mongo_client.py", line 1885, in _tmp_session
[2023-10-19T12:23:27.117+0000] {docker.py:406} INFO - s = self._ensure_session(session)
  File "/usr/local/lib/python3.10/site-packages/pymongo/mongo_client.py", line 1868, in _ensure_session
[2023-10-19T12:23:27.118+0000] {docker.py:406} INFO - return self.__start_session(True, causal_consistency=False)
  File "/usr/local/lib/python3.10/site-packages/pymongo/mongo_client.py", line 1811, in __start_session
[2023-10-19T12:23:27.119+0000] {docker.py:406} INFO - self._topology._check_implicit_session_support()
  File "/usr/local/lib/python3.10/site-packages/pymongo/topology.py", line 583, in _check_implicit_session_support
[2023-10-19T12:23:27.119+0000] {docker.py:406} INFO - self._check_session_support()
  File "/usr/local/lib/python3.10/site-packages/pymongo/topology.py", line 599, in _check_session_support
[2023-10-19T12:23:27.120+0000] {docker.py:406} INFO - self._select_servers_loop(
  File "/usr/local/lib/python3.10/site-packages/pymongo/topology.py", line 269, in _select_servers_loop
[2023-10-19T12:23:27.120+0000] {docker.py:406} INFO - raise ServerSelectionTimeoutError(
pymongo.errors.ServerSelectionTimeoutError: mongo:27017: [Errno -2] Name or service not known, Timeout: 30s, Topology Description: <TopologyDescription id: 65311f9e9cd78dd42024145a, topology_type: Unknown, servers: [<ServerDescription ('mongo', 27017) server_type: Unknown, rtt: None, error=AutoReconnect('mongo:27017: [Errno -2] Name or service not known')>]>
[2023-10-19T12:23:27.958+0000] {taskinstance.py:1937} ERROR - Task failed with exception
Traceback (most recent call last):
  File "/home/airflow/.local/lib/python3.8/site-packages/airflow/providers/docker/operators/docker.py", line 479, in execute
    return self._run_image()
  File "/home/airflow/.local/lib/python3.8/site-packages/airflow/providers/docker/operators/docker.py", line 354, in _run_image
    return self._run_image_with_mounts(self.mounts, add_tmp_variable=False)
  File "/home/airflow/.local/lib/python3.8/site-packages/airflow/providers/docker/operators/docker.py", line 414, in _run_image_with_mounts
    raise DockerContainerFailedException(f"Docker container failed: {result!r}", logs=log_lines)
airflow.providers.docker.exceptions.DockerContainerFailedException: Docker container failed: {'StatusCode': 1}
[2023-10-19T12:23:27.960+0000] {taskinstance.py:1400} INFO - Marking task as FAILED. dag_id=copy_tranform_to_mongo, task_id=load_data_to_mongo, execution_date=20210412T000000, start_date=20231019T122251, end_date=20231019T122327
[2023-10-19T12:23:27.967+0000] {standard_task_runner.py:104} ERROR - Failed to execute job 187 for task load_data_to_mongo (Docker container failed: {'StatusCode': 1}; 728)
[2023-10-19T12:23:27.976+0000] {local_task_job_runner.py:228} INFO - Task exited with return code 1
[2023-10-19T12:23:27.987+0000] {taskinstance.py:2778} INFO - 0 downstream tasks scheduled from follow-on schedule check
