[2023-10-18T11:51:28.316+0000] {taskinstance.py:1159} INFO - Dependencies all met for dep_context=non-requeueable deps ti=<TaskInstance: copy_tranform_to_mongo.transform_data_by_pandas scheduled__2023-05-28T00:00:00+00:00 [queued]>
[2023-10-18T11:51:28.326+0000] {taskinstance.py:1159} INFO - Dependencies all met for dep_context=requeueable deps ti=<TaskInstance: copy_tranform_to_mongo.transform_data_by_pandas scheduled__2023-05-28T00:00:00+00:00 [queued]>
[2023-10-18T11:51:28.326+0000] {taskinstance.py:1361} INFO - Starting attempt 1 of 1
[2023-10-18T11:51:28.340+0000] {taskinstance.py:1382} INFO - Executing <Task(DockerOperator): transform_data_by_pandas> on 2023-05-28 00:00:00+00:00
[2023-10-18T11:51:28.348+0000] {standard_task_runner.py:57} INFO - Started process 4103 to run task
[2023-10-18T11:51:28.358+0000] {standard_task_runner.py:84} INFO - Running: ['***', 'tasks', 'run', 'copy_tranform_to_mongo', 'transform_data_by_pandas', 'scheduled__2023-05-28T00:00:00+00:00', '--job-id', '1724', '--raw', '--subdir', 'DAGS_FOLDER/file_***-mongo.py', '--cfg-path', '/tmp/tmpq84c5qqo']
[2023-10-18T11:51:28.359+0000] {standard_task_runner.py:85} INFO - Job 1724: Subtask transform_data_by_pandas
[2023-10-18T11:51:28.407+0000] {task_command.py:416} INFO - Running <TaskInstance: copy_tranform_to_mongo.transform_data_by_pandas scheduled__2023-05-28T00:00:00+00:00 [running]> on host 0e68aa52dfc7
[2023-10-18T11:51:28.513+0000] {taskinstance.py:1662} INFO - Exporting env vars: AIRFLOW_CTX_DAG_OWNER='***' AIRFLOW_CTX_DAG_ID='copy_tranform_to_mongo' AIRFLOW_CTX_TASK_ID='transform_data_by_pandas' AIRFLOW_CTX_EXECUTION_DATE='2023-05-28T00:00:00+00:00' AIRFLOW_CTX_TRY_NUMBER='1' AIRFLOW_CTX_DAG_RUN_ID='scheduled__2023-05-28T00:00:00+00:00'
[2023-10-18T11:51:28.535+0000] {docker.py:337} INFO - Starting docker container from image python/pandas:1.0.0
[2023-10-18T11:51:28.556+0000] {taskinstance.py:1937} ERROR - Task failed with exception
Traceback (most recent call last):
  File "/home/airflow/.local/lib/python3.8/site-packages/docker/api/client.py", line 268, in _raise_for_status
    response.raise_for_status()
  File "/home/airflow/.local/lib/python3.8/site-packages/requests/models.py", line 1021, in raise_for_status
    raise HTTPError(http_error_msg, response=self)
requests.exceptions.HTTPError: 400 Client Error: Bad Request for url: http+docker://localhost/v1.43/containers/create

The above exception was the direct cause of the following exception:

Traceback (most recent call last):
  File "/home/airflow/.local/lib/python3.8/site-packages/airflow/providers/docker/operators/docker.py", line 479, in execute
    return self._run_image()
  File "/home/airflow/.local/lib/python3.8/site-packages/airflow/providers/docker/operators/docker.py", line 354, in _run_image
    return self._run_image_with_mounts(self.mounts, add_tmp_variable=False)
  File "/home/airflow/.local/lib/python3.8/site-packages/airflow/providers/docker/operators/docker.py", line 369, in _run_image_with_mounts
    self.container = self.cli.create_container(
  File "/home/airflow/.local/lib/python3.8/site-packages/docker/api/container.py", line 431, in create_container
    return self.create_container_from_config(config, name, platform)
  File "/home/airflow/.local/lib/python3.8/site-packages/docker/api/container.py", line 448, in create_container_from_config
    return self._result(res, True)
  File "/home/airflow/.local/lib/python3.8/site-packages/docker/api/client.py", line 274, in _result
    self._raise_for_status(response)
  File "/home/airflow/.local/lib/python3.8/site-packages/docker/api/client.py", line 270, in _raise_for_status
    raise create_api_error_from_http_exception(e) from e
  File "/home/airflow/.local/lib/python3.8/site-packages/docker/errors.py", line 39, in create_api_error_from_http_exception
    raise cls(e, response=response, explanation=explanation) from e
docker.errors.APIError: 400 Client Error for http+docker://localhost/v1.43/containers/create: Bad Request ("create /home/mikvar/Training/projects/airflow: "/home/mikvar/Training/projects/airflow" includes invalid characters for a local volume name, only "[a-zA-Z0-9][a-zA-Z0-9_.-]" are allowed. If you intended to pass a host directory, use absolute path")
[2023-10-18T11:51:28.568+0000] {taskinstance.py:1400} INFO - Marking task as FAILED. dag_id=copy_tranform_to_mongo, task_id=transform_data_by_pandas, execution_date=20230528T000000, start_date=20231018T115128, end_date=20231018T115128
[2023-10-18T11:51:28.629+0000] {standard_task_runner.py:104} ERROR - Failed to execute job 1724 for task transform_data_by_pandas (400 Client Error for http+docker://localhost/v1.43/containers/create: Bad Request ("create /home/mikvar/Training/projects/airflow: "/home/mikvar/Training/projects/airflow" includes invalid characters for a local volume name, only "[a-zA-Z0-9][a-zA-Z0-9_.-]" are allowed. If you intended to pass a host directory, use absolute path"); 4103)
[2023-10-18T11:51:28.658+0000] {local_task_job_runner.py:228} INFO - Task exited with return code 1
[2023-10-18T11:51:28.676+0000] {taskinstance.py:2778} INFO - 0 downstream tasks scheduled from follow-on schedule check
