[2023-10-19T13:04:06.746+0000] {taskinstance.py:1159} INFO - Dependencies all met for dep_context=non-requeueable deps ti=<TaskInstance: copy_tranform_to_mongo.load_data_to_mongo scheduled__2021-01-13T00:00:00+00:00 [queued]>
[2023-10-19T13:04:06.759+0000] {taskinstance.py:1159} INFO - Dependencies all met for dep_context=requeueable deps ti=<TaskInstance: copy_tranform_to_mongo.load_data_to_mongo scheduled__2021-01-13T00:00:00+00:00 [queued]>
[2023-10-19T13:04:06.760+0000] {taskinstance.py:1361} INFO - Starting attempt 1 of 1
[2023-10-19T13:04:06.787+0000] {taskinstance.py:1382} INFO - Executing <Task(DockerOperator): load_data_to_mongo> on 2021-01-13 00:00:00+00:00
[2023-10-19T13:04:06.802+0000] {standard_task_runner.py:57} INFO - Started process 211 to run task
[2023-10-19T13:04:06.808+0000] {standard_task_runner.py:84} INFO - Running: ['***', 'tasks', 'run', 'copy_tranform_to_mongo', 'load_data_to_mongo', 'scheduled__2021-01-13T00:00:00+00:00', '--job-id', '49', '--raw', '--subdir', 'DAGS_FOLDER/file_***-mongo.py', '--cfg-path', '/tmp/tmpcei6act3']
[2023-10-19T13:04:06.810+0000] {standard_task_runner.py:85} INFO - Job 49: Subtask load_data_to_mongo
[2023-10-19T13:04:06.896+0000] {task_command.py:416} INFO - Running <TaskInstance: copy_tranform_to_mongo.load_data_to_mongo scheduled__2021-01-13T00:00:00+00:00 [running]> on host f2b9ba520501
[2023-10-19T13:04:07.018+0000] {taskinstance.py:1662} INFO - Exporting env vars: AIRFLOW_CTX_DAG_OWNER='***' AIRFLOW_CTX_DAG_ID='copy_tranform_to_mongo' AIRFLOW_CTX_TASK_ID='load_data_to_mongo' AIRFLOW_CTX_EXECUTION_DATE='2021-01-13T00:00:00+00:00' AIRFLOW_CTX_TRY_NUMBER='1' AIRFLOW_CTX_DAG_RUN_ID='scheduled__2021-01-13T00:00:00+00:00'
[2023-10-19T13:04:07.043+0000] {docker.py:337} INFO - Starting docker container from image python/pandas:1.0.0
[2023-10-19T13:04:39.428+0000] {docker.py:406} INFO - Traceback (most recent call last):
[2023-10-19T13:04:39.429+0000] {docker.py:406} INFO - File "/opt/pandasapp/script/load_to_mongo.py", line 27, in <module>
    collection.insert_one(doc_to_insert)
  File "/usr/local/lib/python3.10/site-packages/pymongo/collection.py", line 671, in insert_one
    self._insert_one(
  File "/usr/local/lib/python3.10/site-packages/pymongo/collection.py", line 611, in _insert_one
    self.__database.client._retryable_write(acknowledged, _insert_command, session)
  File "/usr/local/lib/python3.10/site-packages/pymongo/mongo_client.py", line 1567, in _retryable_write
    with self._tmp_session(session) as s:
  File "/usr/local/lib/python3.10/contextlib.py", line 135, in __enter__
    return next(self.gen)
  File "/usr/local/lib/python3.10/site-packages/pymongo/mongo_client.py", line 1885, in _tmp_session
[2023-10-19T13:04:39.430+0000] {docker.py:406} INFO - s = self._ensure_session(session)
  File "/usr/local/lib/python3.10/site-packages/pymongo/mongo_client.py", line 1868, in _ensure_session
    return self.__start_session(True, causal_consistency=False)
  File "/usr/local/lib/python3.10/site-packages/pymongo/mongo_client.py", line 1811, in __start_session
    self._topology._check_implicit_session_support()
  File "/usr/local/lib/python3.10/site-packages/pymongo/topology.py", line 583, in _check_implicit_session_support
    self._check_session_support()
  File "/usr/local/lib/python3.10/site-packages/pymongo/topology.py", line 599, in _check_session_support
[2023-10-19T13:04:39.431+0000] {docker.py:406} INFO - self._select_servers_loop(
  File "/usr/local/lib/python3.10/site-packages/pymongo/topology.py", line 269, in _select_servers_loop
[2023-10-19T13:04:39.432+0000] {docker.py:406} INFO - raise ServerSelectionTimeoutError(
pymongo.errors.ServerSelectionTimeoutError: mongo:27017: [Errno -2] Name or service not known, Timeout: 30s, Topology Description: <TopologyDescription id: 65312948c114c674f5f79295, topology_type: Unknown, servers: [<ServerDescription ('mongo', 27017) server_type: Unknown, rtt: None, error=AutoReconnect('mongo:27017: [Errno -2] Name or service not known')>]>
[2023-10-19T13:04:40.730+0000] {taskinstance.py:1937} ERROR - Task failed with exception
Traceback (most recent call last):
  File "/home/airflow/.local/lib/python3.8/site-packages/airflow/providers/docker/operators/docker.py", line 479, in execute
    return self._run_image()
  File "/home/airflow/.local/lib/python3.8/site-packages/airflow/providers/docker/operators/docker.py", line 354, in _run_image
    return self._run_image_with_mounts(self.mounts, add_tmp_variable=False)
  File "/home/airflow/.local/lib/python3.8/site-packages/airflow/providers/docker/operators/docker.py", line 414, in _run_image_with_mounts
    raise DockerContainerFailedException(f"Docker container failed: {result!r}", logs=log_lines)
airflow.providers.docker.exceptions.DockerContainerFailedException: Docker container failed: {'StatusCode': 1}
[2023-10-19T13:04:40.734+0000] {taskinstance.py:1400} INFO - Marking task as FAILED. dag_id=copy_tranform_to_mongo, task_id=load_data_to_mongo, execution_date=20210113T000000, start_date=20231019T130406, end_date=20231019T130440
[2023-10-19T13:04:40.746+0000] {standard_task_runner.py:104} ERROR - Failed to execute job 49 for task load_data_to_mongo (Docker container failed: {'StatusCode': 1}; 211)
[2023-10-19T13:04:40.771+0000] {local_task_job_runner.py:228} INFO - Task exited with return code 1
[2023-10-19T13:04:40.858+0000] {taskinstance.py:2778} INFO - 0 downstream tasks scheduled from follow-on schedule check
