[2023-10-18T11:17:31.680+0000] {taskinstance.py:1159} INFO - Dependencies all met for dep_context=non-requeueable deps ti=<TaskInstance: copy_tranform_to_mongo.transform_data_by_pandas scheduled__2021-04-13T00:00:00+00:00 [queued]>
[2023-10-18T11:17:31.694+0000] {taskinstance.py:1159} INFO - Dependencies all met for dep_context=requeueable deps ti=<TaskInstance: copy_tranform_to_mongo.transform_data_by_pandas scheduled__2021-04-13T00:00:00+00:00 [queued]>
[2023-10-18T11:17:31.695+0000] {taskinstance.py:1361} INFO - Starting attempt 1 of 1
[2023-10-18T11:17:31.711+0000] {taskinstance.py:1382} INFO - Executing <Task(DockerOperator): transform_data_by_pandas> on 2021-04-13 00:00:00+00:00
[2023-10-18T11:17:31.719+0000] {standard_task_runner.py:57} INFO - Started process 483 to run task
[2023-10-18T11:17:31.724+0000] {standard_task_runner.py:84} INFO - Running: ['***', 'tasks', 'run', 'copy_tranform_to_mongo', 'transform_data_by_pandas', 'scheduled__2021-04-13T00:00:00+00:00', '--job-id', '175', '--raw', '--subdir', 'DAGS_FOLDER/file_***-mongo.py', '--cfg-path', '/tmp/tmpczg6srgi']
[2023-10-18T11:17:31.726+0000] {standard_task_runner.py:85} INFO - Job 175: Subtask transform_data_by_pandas
[2023-10-18T11:17:31.777+0000] {task_command.py:416} INFO - Running <TaskInstance: copy_tranform_to_mongo.transform_data_by_pandas scheduled__2021-04-13T00:00:00+00:00 [running]> on host 0e68aa52dfc7
[2023-10-18T11:17:31.858+0000] {taskinstance.py:1662} INFO - Exporting env vars: AIRFLOW_CTX_DAG_OWNER='***' AIRFLOW_CTX_DAG_ID='copy_tranform_to_mongo' AIRFLOW_CTX_TASK_ID='transform_data_by_pandas' AIRFLOW_CTX_EXECUTION_DATE='2021-04-13T00:00:00+00:00' AIRFLOW_CTX_TRY_NUMBER='1' AIRFLOW_CTX_DAG_RUN_ID='scheduled__2021-04-13T00:00:00+00:00'
[2023-10-18T11:17:31.867+0000] {taskinstance.py:1937} ERROR - Task failed with exception
Traceback (most recent call last):
  File "/home/airflow/.local/lib/python3.8/site-packages/urllib3/connectionpool.py", line 714, in urlopen
    httplib_response = self._make_request(
  File "/home/airflow/.local/lib/python3.8/site-packages/urllib3/connectionpool.py", line 415, in _make_request
    conn.request(method, url, **httplib_request_kw)
  File "/home/airflow/.local/lib/python3.8/site-packages/urllib3/connection.py", line 244, in request
    super(HTTPConnection, self).request(method, url, body=body, headers=headers)
  File "/usr/local/lib/python3.8/http/client.py", line 1256, in request
    self._send_request(method, url, body, headers, encode_chunked)
  File "/usr/local/lib/python3.8/http/client.py", line 1302, in _send_request
    self.endheaders(body, encode_chunked=encode_chunked)
  File "/usr/local/lib/python3.8/http/client.py", line 1251, in endheaders
    self._send_output(message_body, encode_chunked=encode_chunked)
  File "/usr/local/lib/python3.8/http/client.py", line 1011, in _send_output
    self.send(msg)
  File "/usr/local/lib/python3.8/http/client.py", line 951, in send
    self.connect()
  File "/home/airflow/.local/lib/python3.8/site-packages/docker/transport/unixconn.py", line 27, in connect
    sock.connect(self.unix_socket)
PermissionError: [Errno 13] Permission denied

During handling of the above exception, another exception occurred:

Traceback (most recent call last):
  File "/home/airflow/.local/lib/python3.8/site-packages/requests/adapters.py", line 486, in send
    resp = conn.urlopen(
  File "/home/airflow/.local/lib/python3.8/site-packages/urllib3/connectionpool.py", line 798, in urlopen
    retries = retries.increment(
  File "/home/airflow/.local/lib/python3.8/site-packages/urllib3/util/retry.py", line 550, in increment
    raise six.reraise(type(error), error, _stacktrace)
  File "/home/airflow/.local/lib/python3.8/site-packages/urllib3/packages/six.py", line 769, in reraise
    raise value.with_traceback(tb)
  File "/home/airflow/.local/lib/python3.8/site-packages/urllib3/connectionpool.py", line 714, in urlopen
    httplib_response = self._make_request(
  File "/home/airflow/.local/lib/python3.8/site-packages/urllib3/connectionpool.py", line 415, in _make_request
    conn.request(method, url, **httplib_request_kw)
  File "/home/airflow/.local/lib/python3.8/site-packages/urllib3/connection.py", line 244, in request
    super(HTTPConnection, self).request(method, url, body=body, headers=headers)
  File "/usr/local/lib/python3.8/http/client.py", line 1256, in request
    self._send_request(method, url, body, headers, encode_chunked)
  File "/usr/local/lib/python3.8/http/client.py", line 1302, in _send_request
    self.endheaders(body, encode_chunked=encode_chunked)
  File "/usr/local/lib/python3.8/http/client.py", line 1251, in endheaders
    self._send_output(message_body, encode_chunked=encode_chunked)
  File "/usr/local/lib/python3.8/http/client.py", line 1011, in _send_output
    self.send(msg)
  File "/usr/local/lib/python3.8/http/client.py", line 951, in send
    self.connect()
  File "/home/airflow/.local/lib/python3.8/site-packages/docker/transport/unixconn.py", line 27, in connect
    sock.connect(self.unix_socket)
urllib3.exceptions.ProtocolError: ('Connection aborted.', PermissionError(13, 'Permission denied'))

During handling of the above exception, another exception occurred:

Traceback (most recent call last):
  File "/home/airflow/.local/lib/python3.8/site-packages/docker/api/client.py", line 214, in _retrieve_server_version
    return self.version(api_version=False)["ApiVersion"]
  File "/home/airflow/.local/lib/python3.8/site-packages/docker/api/daemon.py", line 181, in version
    return self._result(self._get(url), json=True)
  File "/home/airflow/.local/lib/python3.8/site-packages/docker/utils/decorators.py", line 46, in inner
    return f(self, *args, **kwargs)
  File "/home/airflow/.local/lib/python3.8/site-packages/docker/api/client.py", line 237, in _get
    return self.get(url, **self._set_request_timeout(kwargs))
  File "/home/airflow/.local/lib/python3.8/site-packages/requests/sessions.py", line 602, in get
    return self.request("GET", url, **kwargs)
  File "/home/airflow/.local/lib/python3.8/site-packages/requests/sessions.py", line 589, in request
    resp = self.send(prep, **send_kwargs)
  File "/home/airflow/.local/lib/python3.8/site-packages/requests/sessions.py", line 703, in send
    r = adapter.send(request, **kwargs)
  File "/home/airflow/.local/lib/python3.8/site-packages/requests/adapters.py", line 501, in send
    raise ConnectionError(err, request=request)
requests.exceptions.ConnectionError: ('Connection aborted.', PermissionError(13, 'Permission denied'))

During handling of the above exception, another exception occurred:

Traceback (most recent call last):
  File "/home/airflow/.local/lib/python3.8/site-packages/airflow/providers/docker/operators/docker.py", line 462, in execute
    if self.force_pull or not self.cli.images(name=self.image):
  File "/home/airflow/.local/lib/python3.8/site-packages/airflow/providers/docker/operators/docker.py", line 333, in cli
    return self.hook.api_client
  File "/usr/local/lib/python3.8/functools.py", line 967, in __get__
    val = self.func(instance)
  File "/home/airflow/.local/lib/python3.8/site-packages/airflow/providers/docker/hooks/docker.py", line 120, in api_client
    client = APIClient(
  File "/home/airflow/.local/lib/python3.8/site-packages/docker/api/client.py", line 197, in __init__
    self._version = self._retrieve_server_version()
  File "/home/airflow/.local/lib/python3.8/site-packages/docker/api/client.py", line 221, in _retrieve_server_version
    raise DockerException(
docker.errors.DockerException: Error while fetching server API version: ('Connection aborted.', PermissionError(13, 'Permission denied'))
[2023-10-18T11:17:31.883+0000] {taskinstance.py:1400} INFO - Marking task as FAILED. dag_id=copy_tranform_to_mongo, task_id=transform_data_by_pandas, execution_date=20210413T000000, start_date=20231018T111731, end_date=20231018T111731
[2023-10-18T11:17:31.901+0000] {standard_task_runner.py:104} ERROR - Failed to execute job 175 for task transform_data_by_pandas (Error while fetching server API version: ('Connection aborted.', PermissionError(13, 'Permission denied')); 483)
[2023-10-18T11:17:31.940+0000] {local_task_job_runner.py:228} INFO - Task exited with return code 1
[2023-10-18T11:17:31.966+0000] {taskinstance.py:2778} INFO - 0 downstream tasks scheduled from follow-on schedule check
[2023-10-19T12:22:11.963+0000] {taskinstance.py:1159} INFO - Dependencies all met for dep_context=non-requeueable deps ti=<TaskInstance: copy_tranform_to_mongo.transform_data_by_pandas scheduled__2021-04-13T00:00:00+00:00 [queued]>
[2023-10-19T12:22:12.001+0000] {taskinstance.py:1159} INFO - Dependencies all met for dep_context=requeueable deps ti=<TaskInstance: copy_tranform_to_mongo.transform_data_by_pandas scheduled__2021-04-13T00:00:00+00:00 [queued]>
[2023-10-19T12:22:12.002+0000] {taskinstance.py:1361} INFO - Starting attempt 1 of 1
[2023-10-19T12:22:12.035+0000] {taskinstance.py:1382} INFO - Executing <Task(DockerOperator): transform_data_by_pandas> on 2021-04-13 00:00:00+00:00
[2023-10-19T12:22:12.053+0000] {standard_task_runner.py:57} INFO - Started process 686 to run task
[2023-10-19T12:22:12.057+0000] {standard_task_runner.py:84} INFO - Running: ['***', 'tasks', 'run', 'copy_tranform_to_mongo', 'transform_data_by_pandas', 'scheduled__2021-04-13T00:00:00+00:00', '--job-id', '170', '--raw', '--subdir', 'DAGS_FOLDER/file_***-mongo.py', '--cfg-path', '/tmp/tmpd4drcjx0']
[2023-10-19T12:22:12.058+0000] {standard_task_runner.py:85} INFO - Job 170: Subtask transform_data_by_pandas
[2023-10-19T12:22:12.356+0000] {task_command.py:416} INFO - Running <TaskInstance: copy_tranform_to_mongo.transform_data_by_pandas scheduled__2021-04-13T00:00:00+00:00 [running]> on host 6f5df7fea6fd
[2023-10-19T12:22:12.974+0000] {taskinstance.py:1662} INFO - Exporting env vars: AIRFLOW_CTX_DAG_OWNER='***' AIRFLOW_CTX_DAG_ID='copy_tranform_to_mongo' AIRFLOW_CTX_TASK_ID='transform_data_by_pandas' AIRFLOW_CTX_EXECUTION_DATE='2021-04-13T00:00:00+00:00' AIRFLOW_CTX_TRY_NUMBER='1' AIRFLOW_CTX_DAG_RUN_ID='scheduled__2021-04-13T00:00:00+00:00'
[2023-10-19T12:22:13.053+0000] {docker.py:337} INFO - Starting docker container from image python/pandas:1.0.0
[2023-10-19T12:22:14.811+0000] {docker.py:406} INFO - Input Notebook:  /opt/pandasapp/notebooks/tiktok_google_reviews.ipynb
[2023-10-19T12:22:14.820+0000] {docker.py:406} INFO - Output Notebook: /opt/pandasapp/notebooks/tiktok_google_reviews.ipynb
[2023-10-19T12:22:14.927+0000] {docker.py:406} INFO - Executing:   0%|          | 0/27 [00:00<?, ?cell/s]
[2023-10-19T12:22:17.293+0000] {docker.py:406} INFO - Executing notebook with kernel: python3
[2023-10-19T12:22:17.312+0000] {docker.py:406} INFO - Executing:   4%|▎         | 1/27 [00:02<01:01,  2.38s/cell]
[2023-10-19T12:22:20.038+0000] {docker.py:406} INFO - Executing:  15%|█▍        | 4/27 [00:05<00:27,  1.19s/cell]
[2023-10-19T12:22:28.283+0000] {docker.py:406} INFO - Executing:  22%|██▏       | 6/27 [00:13<00:51,  2.47s/cell]
[2023-10-19T12:22:28.394+0000] {docker.py:406} INFO - Executing:  30%|██▉       | 8/27 [00:13<00:29,  1.54s/cell]
[2023-10-19T12:22:28.581+0000] {docker.py:406} INFO - Executing:  33%|███▎      | 9/27 [00:13<00:22,  1.25s/cell]
[2023-10-19T12:22:28.734+0000] {docker.py:406} INFO - Executing:  37%|███▋      | 10/27 [00:13<00:16,  1.01cell/s]
[2023-10-19T12:22:28.865+0000] {docker.py:406} INFO - Executing:  41%|████      | 11/27 [00:13<00:12,  1.29cell/s]
[2023-10-19T12:22:29.297+0000] {docker.py:406} INFO - Executing:  44%|████▍     | 12/27 [00:14<00:10,  1.46cell/s]
[2023-10-19T12:22:29.703+0000] {docker.py:406} INFO - Executing:  48%|████▊     | 13/27 [00:14<00:08,  1.64cell/s]
[2023-10-19T12:22:29.823+0000] {docker.py:406} INFO - Executing:  52%|█████▏    | 14/27 [00:14<00:06,  2.12cell/s]
[2023-10-19T12:22:31.152+0000] {docker.py:406} INFO - Executing:  59%|█████▉    | 16/27 [00:16<00:06,  1.80cell/s]
[2023-10-19T12:22:34.211+0000] {docker.py:406} INFO - Executing:  63%|██████▎   | 17/27 [00:19<00:11,  1.15s/cell]
[2023-10-19T12:22:34.298+0000] {docker.py:406} INFO - Executing:  67%|██████▋   | 18/27 [00:19<00:08,  1.12cell/s]
[2023-10-19T12:22:34.904+0000] {docker.py:406} INFO - Executing:  70%|███████   | 19/27 [00:19<00:06,  1.23cell/s]
[2023-10-19T12:22:37.302+0000] {docker.py:406} INFO - Executing:  74%|███████▍  | 20/27 [00:22<00:08,  1.25s/cell]
[2023-10-19T12:22:38.200+0000] {docker.py:406} INFO - Executing:  78%|███████▊  | 21/27 [00:23<00:06,  1.15s/cell]
[2023-10-19T12:22:40.239+0000] {docker.py:406} INFO - Executing:  81%|████████▏ | 22/27 [00:25<00:07,  1.40s/cell]
[2023-10-19T12:22:41.788+0000] {docker.py:406} INFO - Executing:  85%|████████▌ | 23/27 [00:26<00:05,  1.45s/cell]
[2023-10-19T12:22:42.255+0000] {docker.py:406} INFO - Executing:  93%|█████████▎| 25/27 [00:27<00:01,  1.11cell/s]
[2023-10-19T12:22:46.284+0000] {docker.py:406} INFO - Executing:  96%|█████████▋| 26/27 [00:31<00:01,  1.66s/cell]
[2023-10-19T12:22:46.419+0000] {docker.py:406} INFO - Executing: 100%|██████████| 27/27 [00:31<00:00,  1.27s/cell]
[2023-10-19T12:22:49.638+0000] {docker.py:406} INFO - Executing: 100%|██████████| 27/27 [00:34<00:00,  1.29s/cell]
[2023-10-19T12:22:50.898+0000] {taskinstance.py:1400} INFO - Marking task as SUCCESS. dag_id=copy_tranform_to_mongo, task_id=transform_data_by_pandas, execution_date=20210413T000000, start_date=20231019T122211, end_date=20231019T122250
[2023-10-19T12:22:51.273+0000] {local_task_job_runner.py:228} INFO - Task exited with return code 0
[2023-10-19T12:22:51.399+0000] {taskinstance.py:2778} INFO - 1 downstream tasks scheduled from follow-on schedule check
