[2023-10-17T11:18:54.875+0000] {taskinstance.py:1159} INFO - Dependencies all met for dep_context=non-requeueable deps ti=<TaskInstance: copy_tranform_to_mongo.waiting_for_data scheduled__2021-02-01T00:00:00+00:00 [queued]>
[2023-10-17T11:18:54.882+0000] {taskinstance.py:1159} INFO - Dependencies all met for dep_context=requeueable deps ti=<TaskInstance: copy_tranform_to_mongo.waiting_for_data scheduled__2021-02-01T00:00:00+00:00 [queued]>
[2023-10-17T11:18:54.883+0000] {taskinstance.py:1361} INFO - Starting attempt 1 of 1
[2023-10-17T11:18:54.895+0000] {taskinstance.py:1382} INFO - Executing <Task(FileSensor): waiting_for_data> on 2021-02-01 00:00:00+00:00
[2023-10-17T11:18:54.903+0000] {standard_task_runner.py:57} INFO - Started process 489 to run task
[2023-10-17T11:18:54.906+0000] {standard_task_runner.py:84} INFO - Running: ['***', 'tasks', 'run', 'copy_tranform_to_mongo', 'waiting_for_data', 'scheduled__2021-02-01T00:00:00+00:00', '--job-id', '36', '--raw', '--subdir', 'DAGS_FOLDER/file_***-mongo.py', '--cfg-path', '/tmp/tmpcp13yx0c']
[2023-10-17T11:18:54.907+0000] {standard_task_runner.py:85} INFO - Job 36: Subtask waiting_for_data
[2023-10-17T11:18:54.947+0000] {task_command.py:416} INFO - Running <TaskInstance: copy_tranform_to_mongo.waiting_for_data scheduled__2021-02-01T00:00:00+00:00 [running]> on host 238c1d4ff767
[2023-10-17T11:18:55.017+0000] {taskinstance.py:1662} INFO - Exporting env vars: AIRFLOW_CTX_DAG_OWNER='***' AIRFLOW_CTX_DAG_ID='copy_tranform_to_mongo' AIRFLOW_CTX_TASK_ID='waiting_for_data' AIRFLOW_CTX_EXECUTION_DATE='2021-02-01T00:00:00+00:00' AIRFLOW_CTX_TRY_NUMBER='1' AIRFLOW_CTX_DAG_RUN_ID='scheduled__2021-02-01T00:00:00+00:00'
[2023-10-17T11:18:55.026+0000] {base.py:73} INFO - Using connection ID 'fs_default' for task execution.
[2023-10-17T11:18:55.027+0000] {filesystem.py:64} INFO - Poking for file /opt/in/tiktok_google_play_reviews.csv
[2023-10-17T11:18:55.027+0000] {filesystem.py:69} INFO - Found File /opt/in/tiktok_google_play_reviews.csv last modified: 20220405221612
[2023-10-17T11:18:55.027+0000] {base.py:287} INFO - Success criteria met. Exiting.
[2023-10-17T11:18:55.033+0000] {taskinstance.py:1400} INFO - Marking task as SUCCESS. dag_id=copy_tranform_to_mongo, task_id=waiting_for_data, execution_date=20210201T000000, start_date=20231017T111854, end_date=20231017T111855
[2023-10-17T11:18:55.079+0000] {local_task_job_runner.py:228} INFO - Task exited with return code 0
[2023-10-17T11:18:55.091+0000] {taskinstance.py:2778} INFO - 0 downstream tasks scheduled from follow-on schedule check
[2023-10-18T10:42:23.078+0000] {taskinstance.py:1159} INFO - Dependencies all met for dep_context=non-requeueable deps ti=<TaskInstance: copy_tranform_to_mongo.waiting_for_data scheduled__2021-02-01T00:00:00+00:00 [queued]>
[2023-10-18T10:42:23.087+0000] {taskinstance.py:1159} INFO - Dependencies all met for dep_context=requeueable deps ti=<TaskInstance: copy_tranform_to_mongo.waiting_for_data scheduled__2021-02-01T00:00:00+00:00 [queued]>
[2023-10-18T10:42:23.087+0000] {taskinstance.py:1361} INFO - Starting attempt 1 of 1
[2023-10-18T10:42:23.101+0000] {taskinstance.py:1382} INFO - Executing <Task(FileSensor): waiting_for_data> on 2021-02-01 00:00:00+00:00
[2023-10-18T10:42:23.106+0000] {standard_task_runner.py:57} INFO - Started process 1452 to run task
[2023-10-18T10:42:23.109+0000] {standard_task_runner.py:84} INFO - Running: ['***', 'tasks', 'run', 'copy_tranform_to_mongo', 'waiting_for_data', 'scheduled__2021-02-01T00:00:00+00:00', '--job-id', '35', '--raw', '--subdir', 'DAGS_FOLDER/file_***-mongo.py', '--cfg-path', '/tmp/tmp1cvj_wk0']
[2023-10-18T10:42:23.111+0000] {standard_task_runner.py:85} INFO - Job 35: Subtask waiting_for_data
[2023-10-18T10:42:23.157+0000] {task_command.py:416} INFO - Running <TaskInstance: copy_tranform_to_mongo.waiting_for_data scheduled__2021-02-01T00:00:00+00:00 [running]> on host 2473b23ba069
[2023-10-18T10:42:23.229+0000] {taskinstance.py:1662} INFO - Exporting env vars: AIRFLOW_CTX_DAG_OWNER='***' AIRFLOW_CTX_DAG_ID='copy_tranform_to_mongo' AIRFLOW_CTX_TASK_ID='waiting_for_data' AIRFLOW_CTX_EXECUTION_DATE='2021-02-01T00:00:00+00:00' AIRFLOW_CTX_TRY_NUMBER='1' AIRFLOW_CTX_DAG_RUN_ID='scheduled__2021-02-01T00:00:00+00:00'
[2023-10-18T10:42:23.246+0000] {taskinstance.py:1937} ERROR - Task failed with exception
Traceback (most recent call last):
  File "/home/airflow/.local/lib/python3.8/site-packages/airflow/sensors/base.py", line 257, in execute
    raise e
  File "/home/airflow/.local/lib/python3.8/site-packages/airflow/sensors/base.py", line 239, in execute
    poke_return = self.poke(context)
  File "/home/airflow/.local/lib/python3.8/site-packages/airflow/sensors/filesystem.py", line 61, in poke
    hook = FSHook(self.fs_conn_id)
  File "/home/airflow/.local/lib/python3.8/site-packages/airflow/hooks/filesystem.py", line 38, in __init__
    conn = self.get_connection(conn_id)
  File "/home/airflow/.local/lib/python3.8/site-packages/airflow/hooks/base.py", line 72, in get_connection
    conn = Connection.get_connection_from_secrets(conn_id)
  File "/home/airflow/.local/lib/python3.8/site-packages/airflow/models/connection.py", line 477, in get_connection_from_secrets
    raise AirflowNotFoundException(f"The conn_id `{conn_id}` isn't defined")
airflow.exceptions.AirflowNotFoundException: The conn_id `fs_default` isn't defined
[2023-10-18T10:42:23.252+0000] {taskinstance.py:1400} INFO - Marking task as FAILED. dag_id=copy_tranform_to_mongo, task_id=waiting_for_data, execution_date=20210201T000000, start_date=20231018T104223, end_date=20231018T104223
[2023-10-18T10:42:23.267+0000] {standard_task_runner.py:104} ERROR - Failed to execute job 35 for task waiting_for_data (The conn_id `fs_default` isn't defined; 1452)
[2023-10-18T10:42:23.282+0000] {local_task_job_runner.py:228} INFO - Task exited with return code 1
[2023-10-18T10:42:23.315+0000] {taskinstance.py:2778} INFO - 0 downstream tasks scheduled from follow-on schedule check
[2023-10-18T11:14:53.957+0000] {taskinstance.py:1159} INFO - Dependencies all met for dep_context=non-requeueable deps ti=<TaskInstance: copy_tranform_to_mongo.waiting_for_data scheduled__2021-02-01T00:00:00+00:00 [queued]>
[2023-10-18T11:14:53.968+0000] {taskinstance.py:1159} INFO - Dependencies all met for dep_context=requeueable deps ti=<TaskInstance: copy_tranform_to_mongo.waiting_for_data scheduled__2021-02-01T00:00:00+00:00 [queued]>
[2023-10-18T11:14:53.968+0000] {taskinstance.py:1361} INFO - Starting attempt 1 of 1
[2023-10-18T11:14:53.986+0000] {taskinstance.py:1382} INFO - Executing <Task(FileSensor): waiting_for_data> on 2021-02-01 00:00:00+00:00
[2023-10-18T11:14:53.993+0000] {standard_task_runner.py:57} INFO - Started process 159 to run task
[2023-10-18T11:14:53.996+0000] {standard_task_runner.py:84} INFO - Running: ['***', 'tasks', 'run', 'copy_tranform_to_mongo', 'waiting_for_data', 'scheduled__2021-02-01T00:00:00+00:00', '--job-id', '34', '--raw', '--subdir', 'DAGS_FOLDER/file_***-mongo.py', '--cfg-path', '/tmp/tmp5afaqskt']
[2023-10-18T11:14:53.997+0000] {standard_task_runner.py:85} INFO - Job 34: Subtask waiting_for_data
[2023-10-18T11:14:54.045+0000] {task_command.py:416} INFO - Running <TaskInstance: copy_tranform_to_mongo.waiting_for_data scheduled__2021-02-01T00:00:00+00:00 [running]> on host 0e68aa52dfc7
[2023-10-18T11:14:54.131+0000] {taskinstance.py:1662} INFO - Exporting env vars: AIRFLOW_CTX_DAG_OWNER='***' AIRFLOW_CTX_DAG_ID='copy_tranform_to_mongo' AIRFLOW_CTX_TASK_ID='waiting_for_data' AIRFLOW_CTX_EXECUTION_DATE='2021-02-01T00:00:00+00:00' AIRFLOW_CTX_TRY_NUMBER='1' AIRFLOW_CTX_DAG_RUN_ID='scheduled__2021-02-01T00:00:00+00:00'
[2023-10-18T11:14:54.148+0000] {taskinstance.py:1937} ERROR - Task failed with exception
Traceback (most recent call last):
  File "/home/airflow/.local/lib/python3.8/site-packages/airflow/sensors/base.py", line 257, in execute
    raise e
  File "/home/airflow/.local/lib/python3.8/site-packages/airflow/sensors/base.py", line 239, in execute
    poke_return = self.poke(context)
  File "/home/airflow/.local/lib/python3.8/site-packages/airflow/sensors/filesystem.py", line 61, in poke
    hook = FSHook(self.fs_conn_id)
  File "/home/airflow/.local/lib/python3.8/site-packages/airflow/hooks/filesystem.py", line 38, in __init__
    conn = self.get_connection(conn_id)
  File "/home/airflow/.local/lib/python3.8/site-packages/airflow/hooks/base.py", line 72, in get_connection
    conn = Connection.get_connection_from_secrets(conn_id)
  File "/home/airflow/.local/lib/python3.8/site-packages/airflow/models/connection.py", line 477, in get_connection_from_secrets
    raise AirflowNotFoundException(f"The conn_id `{conn_id}` isn't defined")
airflow.exceptions.AirflowNotFoundException: The conn_id `fs_default` isn't defined
[2023-10-18T11:14:54.152+0000] {taskinstance.py:1400} INFO - Marking task as FAILED. dag_id=copy_tranform_to_mongo, task_id=waiting_for_data, execution_date=20210201T000000, start_date=20231018T111453, end_date=20231018T111454
[2023-10-18T11:14:54.164+0000] {standard_task_runner.py:104} ERROR - Failed to execute job 34 for task waiting_for_data (The conn_id `fs_default` isn't defined; 159)
[2023-10-18T11:14:54.212+0000] {local_task_job_runner.py:228} INFO - Task exited with return code 1
[2023-10-18T11:14:54.231+0000] {taskinstance.py:2778} INFO - 0 downstream tasks scheduled from follow-on schedule check
[2023-10-19T12:10:01.918+0000] {taskinstance.py:1159} INFO - Dependencies all met for dep_context=non-requeueable deps ti=<TaskInstance: copy_tranform_to_mongo.waiting_for_data scheduled__2021-02-01T00:00:00+00:00 [queued]>
[2023-10-19T12:10:01.925+0000] {taskinstance.py:1159} INFO - Dependencies all met for dep_context=requeueable deps ti=<TaskInstance: copy_tranform_to_mongo.waiting_for_data scheduled__2021-02-01T00:00:00+00:00 [queued]>
[2023-10-19T12:10:01.925+0000] {taskinstance.py:1361} INFO - Starting attempt 1 of 1
[2023-10-19T12:10:01.938+0000] {taskinstance.py:1382} INFO - Executing <Task(FileSensor): waiting_for_data> on 2021-02-01 00:00:00+00:00
[2023-10-19T12:10:01.946+0000] {standard_task_runner.py:57} INFO - Started process 227 to run task
[2023-10-19T12:10:01.949+0000] {standard_task_runner.py:84} INFO - Running: ['***', 'tasks', 'run', 'copy_tranform_to_mongo', 'waiting_for_data', 'scheduled__2021-02-01T00:00:00+00:00', '--job-id', '34', '--raw', '--subdir', 'DAGS_FOLDER/file_***-mongo.py', '--cfg-path', '/tmp/tmpzp4kdzb8']
[2023-10-19T12:10:01.950+0000] {standard_task_runner.py:85} INFO - Job 34: Subtask waiting_for_data
[2023-10-19T12:10:01.994+0000] {task_command.py:416} INFO - Running <TaskInstance: copy_tranform_to_mongo.waiting_for_data scheduled__2021-02-01T00:00:00+00:00 [running]> on host 6f5df7fea6fd
[2023-10-19T12:10:02.063+0000] {taskinstance.py:1662} INFO - Exporting env vars: AIRFLOW_CTX_DAG_OWNER='***' AIRFLOW_CTX_DAG_ID='copy_tranform_to_mongo' AIRFLOW_CTX_TASK_ID='waiting_for_data' AIRFLOW_CTX_EXECUTION_DATE='2021-02-01T00:00:00+00:00' AIRFLOW_CTX_TRY_NUMBER='1' AIRFLOW_CTX_DAG_RUN_ID='scheduled__2021-02-01T00:00:00+00:00'
[2023-10-19T12:10:02.078+0000] {taskinstance.py:1937} ERROR - Task failed with exception
Traceback (most recent call last):
  File "/home/airflow/.local/lib/python3.8/site-packages/airflow/sensors/base.py", line 257, in execute
    raise e
  File "/home/airflow/.local/lib/python3.8/site-packages/airflow/sensors/base.py", line 239, in execute
    poke_return = self.poke(context)
  File "/home/airflow/.local/lib/python3.8/site-packages/airflow/sensors/filesystem.py", line 61, in poke
    hook = FSHook(self.fs_conn_id)
  File "/home/airflow/.local/lib/python3.8/site-packages/airflow/hooks/filesystem.py", line 38, in __init__
    conn = self.get_connection(conn_id)
  File "/home/airflow/.local/lib/python3.8/site-packages/airflow/hooks/base.py", line 72, in get_connection
    conn = Connection.get_connection_from_secrets(conn_id)
  File "/home/airflow/.local/lib/python3.8/site-packages/airflow/models/connection.py", line 477, in get_connection_from_secrets
    raise AirflowNotFoundException(f"The conn_id `{conn_id}` isn't defined")
airflow.exceptions.AirflowNotFoundException: The conn_id `fs_default` isn't defined
[2023-10-19T12:10:02.082+0000] {taskinstance.py:1400} INFO - Marking task as FAILED. dag_id=copy_tranform_to_mongo, task_id=waiting_for_data, execution_date=20210201T000000, start_date=20231019T121001, end_date=20231019T121002
[2023-10-19T12:10:02.091+0000] {standard_task_runner.py:104} ERROR - Failed to execute job 34 for task waiting_for_data (The conn_id `fs_default` isn't defined; 227)
[2023-10-19T12:10:02.121+0000] {local_task_job_runner.py:228} INFO - Task exited with return code 1
[2023-10-19T12:10:02.143+0000] {taskinstance.py:2778} INFO - 0 downstream tasks scheduled from follow-on schedule check
