[2023-10-18T11:17:42.714+0000] {taskinstance.py:1159} INFO - Dependencies all met for dep_context=non-requeueable deps ti=<TaskInstance: copy_tranform_to_mongo.transform_data_by_pandas scheduled__2021-05-01T00:00:00+00:00 [queued]>
[2023-10-18T11:17:42.725+0000] {taskinstance.py:1159} INFO - Dependencies all met for dep_context=requeueable deps ti=<TaskInstance: copy_tranform_to_mongo.transform_data_by_pandas scheduled__2021-05-01T00:00:00+00:00 [queued]>
[2023-10-18T11:17:42.725+0000] {taskinstance.py:1361} INFO - Starting attempt 1 of 1
[2023-10-18T11:17:42.737+0000] {taskinstance.py:1382} INFO - Executing <Task(DockerOperator): transform_data_by_pandas> on 2021-05-01 00:00:00+00:00
[2023-10-18T11:17:42.745+0000] {standard_task_runner.py:57} INFO - Started process 560 to run task
[2023-10-18T11:17:42.747+0000] {standard_task_runner.py:84} INFO - Running: ['***', 'tasks', 'run', 'copy_tranform_to_mongo', 'transform_data_by_pandas', 'scheduled__2021-05-01T00:00:00+00:00', '--job-id', '211', '--raw', '--subdir', 'DAGS_FOLDER/file_***-mongo.py', '--cfg-path', '/tmp/tmp7u2m750u']
[2023-10-18T11:17:42.748+0000] {standard_task_runner.py:85} INFO - Job 211: Subtask transform_data_by_pandas
[2023-10-18T11:17:42.820+0000] {task_command.py:416} INFO - Running <TaskInstance: copy_tranform_to_mongo.transform_data_by_pandas scheduled__2021-05-01T00:00:00+00:00 [running]> on host 0e68aa52dfc7
[2023-10-18T11:17:42.937+0000] {taskinstance.py:1662} INFO - Exporting env vars: AIRFLOW_CTX_DAG_OWNER='***' AIRFLOW_CTX_DAG_ID='copy_tranform_to_mongo' AIRFLOW_CTX_TASK_ID='transform_data_by_pandas' AIRFLOW_CTX_EXECUTION_DATE='2021-05-01T00:00:00+00:00' AIRFLOW_CTX_TRY_NUMBER='1' AIRFLOW_CTX_DAG_RUN_ID='scheduled__2021-05-01T00:00:00+00:00'
[2023-10-18T11:17:42.946+0000] {taskinstance.py:1937} ERROR - Task failed with exception
Traceback (most recent call last):
  File "/home/airflow/.local/lib/python3.8/site-packages/urllib3/connectionpool.py", line 714, in urlopen
    httplib_response = self._make_request(
  File "/home/airflow/.local/lib/python3.8/site-packages/urllib3/connectionpool.py", line 415, in _make_request
    conn.request(method, url, **httplib_request_kw)
  File "/home/airflow/.local/lib/python3.8/site-packages/urllib3/connection.py", line 244, in request
    super(HTTPConnection, self).request(method, url, body=body, headers=headers)
  File "/usr/local/lib/python3.8/http/client.py", line 1256, in request
    self._send_request(method, url, body, headers, encode_chunked)
  File "/usr/local/lib/python3.8/http/client.py", line 1302, in _send_request
    self.endheaders(body, encode_chunked=encode_chunked)
  File "/usr/local/lib/python3.8/http/client.py", line 1251, in endheaders
    self._send_output(message_body, encode_chunked=encode_chunked)
  File "/usr/local/lib/python3.8/http/client.py", line 1011, in _send_output
    self.send(msg)
  File "/usr/local/lib/python3.8/http/client.py", line 951, in send
    self.connect()
  File "/home/airflow/.local/lib/python3.8/site-packages/docker/transport/unixconn.py", line 27, in connect
    sock.connect(self.unix_socket)
PermissionError: [Errno 13] Permission denied

During handling of the above exception, another exception occurred:

Traceback (most recent call last):
  File "/home/airflow/.local/lib/python3.8/site-packages/requests/adapters.py", line 486, in send
    resp = conn.urlopen(
  File "/home/airflow/.local/lib/python3.8/site-packages/urllib3/connectionpool.py", line 798, in urlopen
    retries = retries.increment(
  File "/home/airflow/.local/lib/python3.8/site-packages/urllib3/util/retry.py", line 550, in increment
    raise six.reraise(type(error), error, _stacktrace)
  File "/home/airflow/.local/lib/python3.8/site-packages/urllib3/packages/six.py", line 769, in reraise
    raise value.with_traceback(tb)
  File "/home/airflow/.local/lib/python3.8/site-packages/urllib3/connectionpool.py", line 714, in urlopen
    httplib_response = self._make_request(
  File "/home/airflow/.local/lib/python3.8/site-packages/urllib3/connectionpool.py", line 415, in _make_request
    conn.request(method, url, **httplib_request_kw)
  File "/home/airflow/.local/lib/python3.8/site-packages/urllib3/connection.py", line 244, in request
    super(HTTPConnection, self).request(method, url, body=body, headers=headers)
  File "/usr/local/lib/python3.8/http/client.py", line 1256, in request
    self._send_request(method, url, body, headers, encode_chunked)
  File "/usr/local/lib/python3.8/http/client.py", line 1302, in _send_request
    self.endheaders(body, encode_chunked=encode_chunked)
  File "/usr/local/lib/python3.8/http/client.py", line 1251, in endheaders
    self._send_output(message_body, encode_chunked=encode_chunked)
  File "/usr/local/lib/python3.8/http/client.py", line 1011, in _send_output
    self.send(msg)
  File "/usr/local/lib/python3.8/http/client.py", line 951, in send
    self.connect()
  File "/home/airflow/.local/lib/python3.8/site-packages/docker/transport/unixconn.py", line 27, in connect
    sock.connect(self.unix_socket)
urllib3.exceptions.ProtocolError: ('Connection aborted.', PermissionError(13, 'Permission denied'))

During handling of the above exception, another exception occurred:

Traceback (most recent call last):
  File "/home/airflow/.local/lib/python3.8/site-packages/docker/api/client.py", line 214, in _retrieve_server_version
    return self.version(api_version=False)["ApiVersion"]
  File "/home/airflow/.local/lib/python3.8/site-packages/docker/api/daemon.py", line 181, in version
    return self._result(self._get(url), json=True)
  File "/home/airflow/.local/lib/python3.8/site-packages/docker/utils/decorators.py", line 46, in inner
    return f(self, *args, **kwargs)
  File "/home/airflow/.local/lib/python3.8/site-packages/docker/api/client.py", line 237, in _get
    return self.get(url, **self._set_request_timeout(kwargs))
  File "/home/airflow/.local/lib/python3.8/site-packages/requests/sessions.py", line 602, in get
    return self.request("GET", url, **kwargs)
  File "/home/airflow/.local/lib/python3.8/site-packages/requests/sessions.py", line 589, in request
    resp = self.send(prep, **send_kwargs)
  File "/home/airflow/.local/lib/python3.8/site-packages/requests/sessions.py", line 703, in send
    r = adapter.send(request, **kwargs)
  File "/home/airflow/.local/lib/python3.8/site-packages/requests/adapters.py", line 501, in send
    raise ConnectionError(err, request=request)
requests.exceptions.ConnectionError: ('Connection aborted.', PermissionError(13, 'Permission denied'))

During handling of the above exception, another exception occurred:

Traceback (most recent call last):
  File "/home/airflow/.local/lib/python3.8/site-packages/airflow/providers/docker/operators/docker.py", line 462, in execute
    if self.force_pull or not self.cli.images(name=self.image):
  File "/home/airflow/.local/lib/python3.8/site-packages/airflow/providers/docker/operators/docker.py", line 333, in cli
    return self.hook.api_client
  File "/usr/local/lib/python3.8/functools.py", line 967, in __get__
    val = self.func(instance)
  File "/home/airflow/.local/lib/python3.8/site-packages/airflow/providers/docker/hooks/docker.py", line 120, in api_client
    client = APIClient(
  File "/home/airflow/.local/lib/python3.8/site-packages/docker/api/client.py", line 197, in __init__
    self._version = self._retrieve_server_version()
  File "/home/airflow/.local/lib/python3.8/site-packages/docker/api/client.py", line 221, in _retrieve_server_version
    raise DockerException(
docker.errors.DockerException: Error while fetching server API version: ('Connection aborted.', PermissionError(13, 'Permission denied'))
[2023-10-18T11:17:42.964+0000] {taskinstance.py:1400} INFO - Marking task as FAILED. dag_id=copy_tranform_to_mongo, task_id=transform_data_by_pandas, execution_date=20210501T000000, start_date=20231018T111742, end_date=20231018T111742
[2023-10-18T11:17:42.983+0000] {standard_task_runner.py:104} ERROR - Failed to execute job 211 for task transform_data_by_pandas (Error while fetching server API version: ('Connection aborted.', PermissionError(13, 'Permission denied')); 560)
[2023-10-18T11:17:43.005+0000] {local_task_job_runner.py:228} INFO - Task exited with return code 1
[2023-10-18T11:17:43.070+0000] {taskinstance.py:2778} INFO - 0 downstream tasks scheduled from follow-on schedule check
[2023-10-19T12:42:59.464+0000] {taskinstance.py:1159} INFO - Dependencies all met for dep_context=non-requeueable deps ti=<TaskInstance: copy_tranform_to_mongo.transform_data_by_pandas scheduled__2021-05-01T00:00:00+00:00 [queued]>
[2023-10-19T12:42:59.494+0000] {taskinstance.py:1159} INFO - Dependencies all met for dep_context=requeueable deps ti=<TaskInstance: copy_tranform_to_mongo.transform_data_by_pandas scheduled__2021-05-01T00:00:00+00:00 [queued]>
[2023-10-19T12:42:59.494+0000] {taskinstance.py:1361} INFO - Starting attempt 1 of 1
[2023-10-19T12:42:59.527+0000] {taskinstance.py:1382} INFO - Executing <Task(DockerOperator): transform_data_by_pandas> on 2021-05-01 00:00:00+00:00
[2023-10-19T12:42:59.539+0000] {standard_task_runner.py:84} INFO - Running: ['***', 'tasks', 'run', 'copy_tranform_to_mongo', 'transform_data_by_pandas', 'scheduled__2021-05-01T00:00:00+00:00', '--job-id', '225', '--raw', '--subdir', 'DAGS_FOLDER/file_***-mongo.py', '--cfg-path', '/tmp/tmpffyk9_nh']
[2023-10-19T12:42:59.541+0000] {standard_task_runner.py:85} INFO - Job 225: Subtask transform_data_by_pandas
[2023-10-19T12:42:59.536+0000] {standard_task_runner.py:57} INFO - Started process 1106 to run task
[2023-10-19T12:42:59.666+0000] {task_command.py:416} INFO - Running <TaskInstance: copy_tranform_to_mongo.transform_data_by_pandas scheduled__2021-05-01T00:00:00+00:00 [running]> on host 6f5df7fea6fd
[2023-10-19T12:42:59.851+0000] {taskinstance.py:1662} INFO - Exporting env vars: AIRFLOW_CTX_DAG_OWNER='***' AIRFLOW_CTX_DAG_ID='copy_tranform_to_mongo' AIRFLOW_CTX_TASK_ID='transform_data_by_pandas' AIRFLOW_CTX_EXECUTION_DATE='2021-05-01T00:00:00+00:00' AIRFLOW_CTX_TRY_NUMBER='1' AIRFLOW_CTX_DAG_RUN_ID='scheduled__2021-05-01T00:00:00+00:00'
[2023-10-19T12:42:59.892+0000] {docker.py:337} INFO - Starting docker container from image python/pandas:1.0.0
[2023-10-19T12:43:01.131+0000] {docker.py:406} INFO - Input Notebook:  /opt/pandasapp/notebooks/tiktok_google_reviews.ipynb
[2023-10-19T12:43:01.141+0000] {docker.py:406} INFO - Output Notebook: /opt/pandasapp/notebooks/tiktok_google_reviews.ipynb
[2023-10-19T12:43:01.274+0000] {docker.py:406} INFO - Executing:   0%|          | 0/27 [00:00<?, ?cell/s]
[2023-10-19T12:43:02.973+0000] {docker.py:406} INFO - Executing notebook with kernel: python3
[2023-10-19T12:43:02.984+0000] {docker.py:406} INFO - Executing:   4%|▎         | 1/27 [00:01<00:44,  1.71s/cell]
[2023-10-19T12:43:07.629+0000] {docker.py:406} INFO - Executing:  15%|█▍        | 4/27 [00:06<00:36,  1.58s/cell]
[2023-10-19T12:43:18.519+0000] {docker.py:406} INFO - Executing:  22%|██▏       | 6/27 [00:17<01:08,  3.26s/cell]
[2023-10-19T12:43:18.639+0000] {docker.py:406} INFO - Executing:  26%|██▌       | 7/27 [00:17<00:50,  2.52s/cell]
[2023-10-19T12:43:18.851+0000] {docker.py:406} INFO - Executing:  33%|███▎      | 9/27 [00:17<00:27,  1.54s/cell]
[2023-10-19T12:43:19.030+0000] {docker.py:406} INFO - Executing:  37%|███▋      | 10/27 [00:17<00:21,  1.24s/cell]
[2023-10-19T12:43:19.147+0000] {docker.py:406} INFO - Executing:  41%|████      | 11/27 [00:17<00:15,  1.04cell/s]
[2023-10-19T12:43:19.566+0000] {docker.py:406} INFO - Executing:  44%|████▍     | 12/27 [00:18<00:12,  1.21cell/s]
[2023-10-19T12:43:19.761+0000] {docker.py:406} INFO - Executing:  48%|████▊     | 13/27 [00:18<00:09,  1.52cell/s]
[2023-10-19T12:43:19.866+0000] {docker.py:406} INFO - Executing:  56%|█████▌    | 15/27 [00:18<00:04,  2.54cell/s]
[2023-10-19T12:43:20.290+0000] {docker.py:406} INFO - Executing:  59%|█████▉    | 16/27 [00:19<00:04,  2.49cell/s]
[2023-10-19T12:43:22.173+0000] {docker.py:406} INFO - Executing:  63%|██████▎   | 17/27 [00:20<00:07,  1.29cell/s]
[2023-10-19T12:43:22.287+0000] {docker.py:406} INFO - Executing:  67%|██████▋   | 18/27 [00:21<00:05,  1.67cell/s]
[2023-10-19T12:43:23.088+0000] {docker.py:406} INFO - Executing:  70%|███████   | 19/27 [00:21<00:05,  1.53cell/s]
[2023-10-19T12:43:25.250+0000] {docker.py:406} INFO - Executing:  74%|███████▍  | 20/27 [00:23<00:07,  1.08s/cell]
[2023-10-19T12:43:25.888+0000] {docker.py:406} INFO - Executing:  78%|███████▊  | 21/27 [00:24<00:05,  1.05cell/s]
[2023-10-19T12:43:27.609+0000] {docker.py:406} INFO - Executing:  81%|████████▏ | 22/27 [00:26<00:05,  1.17s/cell]
[2023-10-19T12:43:28.939+0000] {docker.py:406} INFO - Executing:  85%|████████▌ | 23/27 [00:27<00:04,  1.22s/cell]
[2023-10-19T12:43:29.057+0000] {docker.py:406} INFO - Executing:  89%|████████▉ | 24/27 [00:27<00:02,  1.12cell/s]
[2023-10-19T12:43:29.443+0000] {docker.py:406} INFO - Executing:  93%|█████████▎| 25/27 [00:28<00:01,  1.34cell/s]
[2023-10-19T12:43:33.769+0000] {docker.py:406} INFO - Executing:  96%|█████████▋| 26/27 [00:32<00:01,  1.81s/cell]
[2023-10-19T12:43:36.835+0000] {docker.py:406} INFO - Executing: 100%|██████████| 27/27 [00:35<00:00,  1.32s/cell]
[2023-10-19T12:43:37.956+0000] {taskinstance.py:1400} INFO - Marking task as SUCCESS. dag_id=copy_tranform_to_mongo, task_id=transform_data_by_pandas, execution_date=20210501T000000, start_date=20231019T124259, end_date=20231019T124337
[2023-10-19T12:43:38.101+0000] {local_task_job_runner.py:228} INFO - Task exited with return code 0
[2023-10-19T12:43:38.213+0000] {taskinstance.py:2778} INFO - 1 downstream tasks scheduled from follow-on schedule check
